Workbook

Sheet Start Here
B1: Disaster Recovery Plan | E1: [ YOUR LOGO HERE ] Insert > Pictures, place over this box, then delete this text
B2: Information Gathering Workbook
B3: A self-guided intake tool for IT teams. Complete it before writing the DR plan; the plan is only as good as what's collected here.
B5: Prepared by | D5: Your MSP / consultant name
B6: Prepared for | D6: Client organization name — appears in every tab title
B7: Issued / due date | D7: Date issued and date responses are due
B8: Questions? Contact | D8: Name, email, phone of the person supporting this intake
B10: HOW TO USE THIS WORKBOOK
B11: 1. Fill in Prepared by / Prepared for above (it flows into every tab title). Then assign an owner for each tab (suggested owners are in the tab guide below). IT can't answer the business questions alone — tabs 2, 4, and 9 need department heads.
B12: 2. Work roughly in order: Org Profile → Business Impact → Critical Apps. Business requirements (RTO / RPO) should drive the technical answers, not the other way around.
B13: 3. Type only in light-blue cells. Use the dropdowns where offered. Pink columns calculate automatically. Row 5 on each tab is a gray example — overwrite or delete it.
B14: 4. 'Unknown' is a valid answer. Don't stall on it — record it, and log it on tab 13 (Gaps & Actions). Unknowns ARE the findings.
B15: 5. Never record passwords, secrets, or MFA seeds here. Record where they're stored and who can reach them.
B16: 6. Watch the Readiness Snapshot below. Red flags on tabs 2, 7, and 8 are the issues most likely to turn an outage into a disaster.
B17: 7. This workbook contains sensitive information (contacts, IPs, account numbers). Store and share it like you would the DR plan itself — and keep an offline copy.
B19: LEGEND
B20: Light blue | C20: Input — type here
B21: Pink | C21: Calculated — don't edit
B22: Gray italic | C22: Example row — overwrite or delete
B23: Red | C23: Gap / expired / never tested
B24: Amber | C24: Expiring within warning window
B25: Green | C25: Meets requirement
B26: Tier thresholds, restore-test age, and expiry warning window are adjustable on the Lists tab.
B28: TAB GUIDE & PROGRESS
B29: Tab | C29: What it captures | D29: Suggested owner | E29: Entries / answered
B30: 1 Org Profile | C30: Scope, declaration authority, regulatory drivers, cyber insurance requirements | D30: IT lead + executive sponsor | E30: =COUNTA('1 Org Profile'!B4:B32)&" of 24 answered" -> 0 of 24 answered
B31: 2 Business Impact | C31: Business functions, impact ratings, MTD / RTO / RPO, workarounds | D31: Department heads (IT facilitates) | E31: =COUNTA('2 Business Impact'!A6:A105) -> 0
B32: 3 Critical Apps | C32: Applications, owners, tiers, RTO / RPO, dependencies, restore order | D32: IT + application owners | E32: =COUNTA('3 Critical Apps'!A6:A105) -> 0
B33: 4 Data Inventory | C33: Where data lives, data owners, classification, retention | D33: Data owners + IT | E33: =COUNTA('4 Data Inventory'!A6:A105) -> 0
B34: 5 Infrastructure | C34: Servers, hypervisors, storage, network gear, cloud tenants, recovery method | D34: IT / MSP | E34: =COUNTA('5 Infrastructure'!A6:A105) -> 0
B35: 6 Network | C35: Circuits, VPN, DNS, domains, certificates, email routing, telephony | D35: IT / MSP | E35: =COUNTA('6 Network'!A6:A105) -> 0
B36: 7 Backups | C36: Backup jobs, immutability, restore testing, RPO / RTO gap checks | D36: IT / MSP | E36: =COUNTA('7 Backups'!A6:A105) -> 0
B37: 8 Break-Glass Access | C37: Privileged and emergency accounts, where creds live, offline reachability | D37: IT lead | E37: =COUNTA('8 Break-Glass Access'!A6:A105) -> 0
B38: 9 Internal Contacts | C38: Recovery team, DR roles, out-of-band contact info, authority | D38: IT lead + HR | E38: =COUNTA('9 Internal Contacts'!A6:A105) -> 0
B39: 10 Vendors | C39: Third parties, account numbers, support / escalation, contracts | D39: IT + procurement / finance | E39: =COUNTA('10 Vendors'!A6:A105) -> 0
B40: 11 Recovery Sites | C40: Alternate locations, recovery regions, spare hardware, procurement | D40: IT + facilities | E40: =COUNTA('11 Recovery Sites'!A6:A105) -> 0
B41: 12 Communications | C41: Who notifies whom, how, and with what approval | D41: Leadership + marketing / HR | E41: =COUNTA('12 Communications'!A6:A105) -> 0
B42: 13 Gaps & Actions | C42: Unknowns and findings — becomes the remediation roadmap | D42: DR plan owner | E42: =COUNTA('13 Gaps & Actions'!A6:A105) -> 0
B44: READINESS SNAPSHOT (updates as tabs are completed)
B45: Check | D45: Count | E45: What good looks like
...

Sheet 1 Org Profile
A1: =IF(PreparedFor="","Organization Profile & DR Program Ownership","Organization Profile & DR Program Ownership | "&PreparedFor) -> Organization Profile & DR Program Ownership
A2: Answer each question in the blue Response column. This frames scope, authority, and the regulatory and insurance obligations that shape every recovery decision. Usually completed by the IT lead with input from leadership.
A3: Question | B3: Response | C3: Why it matters / guidance
A4: ORGANIZATION
A5: Organization legal name
A6: Industry / sector
A7: Number of employees / end users
A8: Number of physical locations (detail them on tab 11)
A9: Hours of operation and any 24x7 functions | C9: Sets expectations for when an outage actually hurts and when recovery staff are needed.
A10: Seasonal or cyclical critical periods (month-end, enrollment, tax season, etc.) | C10: A 24-hour outage in a quiet week and in month-end close are different disasters.
A11: DR PROGRAM OWNERSHIP
A12: Executive sponsor for DR (name / title) | C12: Someone with budget authority must own the plan, not just IT.
A13: DR plan owner / coordinator (name / title) | C13: Responsible for keeping this workbook and the resulting plan current.
A14: Who has authority to declare a disaster? List the role and at least two alternates. | C14: Declaration triggers spending, vendor engagement, and insurance clocks. Ambiguity here costs hours.
A15: Existing DR / BC plan? Location and last-updated date
A16: Date and type of last DR test or tabletop exercise | C16: Tabletop, partial restore, full failover — be specific.
A17: Spending authority during a declared disaster (who, and up to what amount) | C17: Emergency hardware, cloud spend, and IR retainers need pre-approved limits.
A18: REGULATORY & CONTRACTUAL DRIVERS
A19: Regulations that apply (HIPAA, CMMC, PCI DSS, FERPA, CJIS, GLBA, state privacy laws, etc.) | C19: Drives notification timelines, evidence preservation, and where data may be restored.
A20: Contractual uptime / recovery commitments to customers or funders | C20: Your customers' SLAs can set your RTO for you.
A21: Breach notification obligations (regulators, states, customers) and timelines | C21: e.g. DFARS 72-hour reporting, HIPAA 60-day, state AG notifications.
A22: Data residency or sovereignty restrictions on recovery locations | C22: Limits which cloud regions or recovery sites are allowed.
A23: CYBER INSURANCE
A24: Carrier, policy number, and policy period
A25: Insurer incident / breach hotline (the required FIRST call) | C25: Many policies reduce or deny coverage if you engage vendors before calling the carrier.
A26: Panel / pre-approved incident response firm and breach counsel | C26: Using non-panel vendors may not be reimbursed.
A27: Policy conditions affecting recovery (MFA, EDR, immutable backups, offline copies, ransom payment terms) | C27: Attestations made on the application must match reality or coverage is at risk.
A28: SCOPE & ASSUMPTIONS
A29: Scenarios in scope (ransomware, site loss, cloud / SaaS outage, ISP outage, key-person loss, insider, etc.) | C29: Ransomware should almost always be in scope; it assumes your domain and backups are hostile.
A30: Systems, locations, or business units explicitly OUT of scope
A31: Known single points of failure — people, systems, or vendors | C31: The person who 'just knows how it works' counts.
A32: Leadership's biggest DR concern today | C32: Use this to prioritize what gets built first.

Sheet 2 Business Impact
A1: =IF(PreparedFor="","Business Impact Analysis","Business Impact Analysis | "&PreparedFor) -> Business Impact Analysis
A2: List the business FUNCTIONS (not systems) the organization must keep running, and how long each can be down. Complete with each department head — IT should facilitate, not guess. Hours are the unit for every downtime / data-loss column. Row 5 (gray, italic) is an EXAMPLE — overwrite or delete it. Pink columns calculate automatically; don't type in them.
A3: Business Function / Process | B3: Department | C3: Process Owner (name / title) | D3: Description | E3: Supporting Applications | F3: Peak / Critical Periods | G3: Financial Impact | H3: Operational Impact | I3: Regulatory / Legal Impact | J3: Reputational Impact | K3: Max Tolerable Downtime (hrs) | L3: Target RTO (hrs) | M3: Target RPO (hrs) | N3: Manual Workaround? | O3: Workaround Description & How Long It Can Be Sustained | P3: Suggested Tier (calc) | Q3: RTO vs MTD Check (calc) | R3: Notes
A4: What the business does, e.g. 'Payroll', 'Student attendance', 'Order fulfillment'. | C4: The business person accountable for this function. | E4: Names should match tab 3. | K4: Point at which the outage causes unacceptable harm. | L4: How fast it must be restored. Must be ≤ MTD. | M4: How much data (in hours) can be lost and re-entered.
A5: Payroll processing | B5: Finance | C5: Jane Doe, Controller | D5: Bi-weekly payroll for 240 employees | E5: Paylocity; Microsoft Excel | F5: Every other Thursday; year-end | G5: High | H5: High | I5: High | J5: Medium | K5: 72 | L5: 24 | M5: 24 | N5: Yes | O5: Re-run prior period as manual checks; sustainable 1 cycle | P5: =IF(K5="","",IF(K5<=Tier1Max,"Tier 1",IF(K5<=Tier2Max,"Tier 2",IF(K5<=Tier3Max,"Tier 3","Tier 4")))) -> Tier 3 | Q5: =IF(OR(K5="",L5=""),"",IF(L5>K5,"RTO > MTD","OK")) -> OK
P6: =IF(K6="","",IF(K6<=Tier1Max,"Tier 1",IF(K6<=Tier2Max,"Tier 2",IF(K6<=Tier3Max,"Tier 3","Tier 4")))) | Q6: =IF(OR(K6="",L6=""),"",IF(L6>K6,"RTO > MTD","OK"))
P7: =IF(K7="","",IF(K7<=Tier1Max,"Tier 1",IF(K7<=Tier2Max,"Tier 2",IF(K7<=Tier3Max,"Tier 3","Tier 4")))) | Q7: =IF(OR(K7="",L7=""),"",IF(L7>K7,"RTO > MTD","OK"))
P8: =IF(K8="","",IF(K8<=Tier1Max,"Tier 1",IF(K8<=Tier2Max,"Tier 2",IF(K8<=Tier3Max,"Tier 3","Tier 4")))) | Q8: =IF(OR(K8="",L8=""),"",IF(L8>K8,"RTO > MTD","OK"))
P9: =IF(K9="","",IF(K9<=Tier1Max,"Tier 1",IF(K9<=Tier2Max,"Tier 2",IF(K9<=Tier3Max,"Tier 3","Tier 4")))) | Q9: =IF(OR(K9="",L9=""),"",IF(L9>K9,"RTO > MTD","OK"))
P10: =IF(K10="","",IF(K10<=Tier1Max,"Tier 1",IF(K10<=Tier2Max,"Tier 2",IF(K10<=Tier3Max,"Tier 3","Tier 4")))) | Q10: =IF(OR(K10="",L10=""),"",IF(L10>K10,"RTO > MTD","OK"))
P11: =IF(K11="","",IF(K11<=Tier1Max,"Tier 1",IF(K11<=Tier2Max,"Tier 2",IF(K11<=Tier3Max,"Tier 3","Tier 4")))) | Q11: =IF(OR(K11="",L11=""),"",IF(L11>K11,"RTO > MTD","OK"))
P12: =IF(K12="","",IF(K12<=Tier1Max,"Tier 1",IF(K12<=Tier2Max,"Tier 2",IF(K12<=Tier3Max,"Tier 3","Tier 4")))) | Q12: =IF(OR(K12="",L12=""),"",IF(L12>K12,"RTO > MTD","OK"))
P13: =IF(K13="","",IF(K13<=Tier1Max,"Tier 1",IF(K13<=Tier2Max,"Tier 2",IF(K13<=Tier3Max,"Tier 3","Tier 4")))) | Q13: =IF(OR(K13="",L13=""),"",IF(L13>K13,"RTO > MTD","OK"))
P14: =IF(K14="","",IF(K14<=Tier1Max,"Tier 1",IF(K14<=Tier2Max,"Tier 2",IF(K14<=Tier3Max,"Tier 3","Tier 4")))) | Q14: =IF(OR(K14="",L14=""),"",IF(L14>K14,"RTO > MTD","OK"))
P15: =IF(K15="","",IF(K15<=Tier1Max,"Tier 1",IF(K15<=Tier2Max,"Tier 2",IF(K15<=Tier3Max,"Tier 3","Tier 4")))) | Q15: =IF(OR(K15="",L15=""),"",IF(L15>K15,"RTO > MTD","OK"))
P16: =IF(K16="","",IF(K16<=Tier1Max,"Tier 1",IF(K16<=Tier2Max,"Tier 2",IF(K16<=Tier3Max,"Tier 3","Tier 4")))) | Q16: =IF(OR(K16="",L16=""),"",IF(L16>K16,"RTO > MTD","OK"))
P17: =IF(K17="","",IF(K17<=Tier1Max,"Tier 1",IF(K17<=Tier2Max,"Tier 2",IF(K17<=Tier3Max,"Tier 3","Tier 4")))) | Q17: =IF(OR(K17="",L17=""),"",IF(L17>K17,"RTO > MTD","OK"))
... P105: =IF(K105="","",IF(K105<=Tier1Max,"Tier 1",IF(K105<=Tier2Max,"Tier 2",IF(K105<=Tier3Max,"Tier 3","Tier 4")))) | Q105: =IF(OR(K105="",L105=""),"",IF(L105>K105,"RTO > MTD","OK"))

Sheet 3 Critical Apps
A1: =IF(PreparedFor="","Critical Applications","Critical Applications | "&PreparedFor) -> Critical Applications
A2: One row per application or service the business depends on — on-prem, cloud, and SaaS. The app name in column A feeds the dropdown on the Backups tab, so use consistent names. RTO / RPO in hours. Row 5 (gray, italic) is an EXAMPLE — overwrite or delete it. Pink columns calculate automatically; don't type in them.
A3: Application / Service Name | B3: Version / Edition | C3: Vendor / Publisher | D3: Hosting Model | E3: Business Functions Supported | F3: Business Owner | G3: Technical Owner / Admin | H3: Criticality Tier | I3: RTO (hrs) | J3: RPO (hrs) | K3: Restore Sequence # | L3: Depends On (servers, databases, other apps, network) | M3: Authentication | N3: Licensing / Activation Constraints | O3: Vendor Support Contact | P3: Install Media / License Keys Location | Q3: Recovery Documentation Location | R3: Is It Backed Up? | S3: Notes
E4: Should match tab 2. | H4: Use the highest tier of any function it supports. | K4: Order of recovery. 1 = first (identity, DNS, network usually come before apps). | L4: What must be up before this works. | N4: Hardware-locked licenses, license servers, vendor activation calls. | O4: Full detail goes on tab 10. | Q4: Runbook, KB article, or 'None' — 'None' is a valid and useful answer. | R4: Detail goes on tab 7. SaaS is NOT automatically backed up.
A5: Paylocity | B5: SaaS – Enterprise | C5: Paylocity Corp. | D5: SaaS | E5: Payroll processing; HR onboarding | F5: Jane Doe, Controller | G5: Sam Lee, Sys Admin | H5: Tier 3 | I5: 24 | J5: 24 | K5: 8 | L5: Entra ID SSO; internet; Excel export to file share | M5: Entra ID / SSO | N5: None – subscription | O5: See tab 10 | P5: N/A (SaaS) | Q5: IT Glue > Paylocity > Recovery | R5: No

Sheet 4 Data Inventory
A1: =IF(PreparedFor="","Data Inventory & Data Owners","Data Inventory & Data Owners | "&PreparedFor) -> Data Inventory & Data Owners
A2: Where the organization's important data lives, who owns it, and how it's protected. Data owners decide classification and retention; IT is the custodian. Include file shares, databases, SaaS repositories, and email. Row 5 (gray, italic) is an EXAMPLE — overwrite or delete it. Pink columns calculate automatically; don't type in them.
A3: Data Set / Repository | B3: Description | C3: Storage Location (system / path / tenant) | D3: Associated Application | E3: Data Owner (business) | F3: Data Custodian (IT) | G3: Classification | H3: Regulatory Scope | I3: Approx. Volume (GB) | J3: Change Rate / Activity | K3: Retention Requirement | L3: Legal Hold Applicable? | M3: Backed Up? | N3: Backup Job Reference (tab 7) | O3: Encrypted at Rest? | P3: Notes
J4: e.g. 'Daily heavy', 'Weekly', 'Archive only'.
A5: Finance file share | B5: AP/AR workpapers, payroll exports | C5: \\FS01\Finance (SharePoint migration planned) | D5: Paylocity | E5: Jane Doe, Controller | F5: Sam Lee, Sys Admin | G5: Confidential | H5: None | I5: 450 | J5: Daily, heavy at month-end | K5: 7 years | L5: No | M5: Yes | N5: FS01-Nightly | O5: Yes

Sheet 5 Infrastructure
A1: =IF(PreparedFor="","Infrastructure Inventory","Infrastructure Inventory | "&PreparedFor) -> Infrastructure Inventory
A2: Servers, hypervisors, storage, network gear, and cloud tenants that the critical apps run on. Export from your RMM / documentation platform if possible and paste here — then fill the recovery columns, which exports never have. Row 5 (gray, italic) is an EXAMPLE — overwrite or delete it. Pink columns calculate automatically; don't type in them.
A3: Asset Name / Hostname | B3: Asset Type | C3: Site / Location | D3: Role / Function | E3: OS / Firmware & Version | F3: Runs On (host / cluster / region) | G3: IP Address(es) | H3: Applications Hosted | I3: Manufacturer / Model | J3: Serial / Service Tag | K3: Warranty / Support Expiry | L3: Technical Owner | M3: Recovery Method | N3: Config Backed Up? | O3: Rebuild Documentation Location | P3: Notes
K4: Red = expired, amber = within warning window (Lists tab). | N4: Firewalls, switches, hypervisor configs count.
A5: FS01 | B5: Virtual machine | C5: HQ server room | D5: File server | E5: Windows Server 2022 | F5: HV-HOST-01 | G5: 10.10.1.20 | H5: Finance and HR shares | I5: N/A (VM) | J5: N/A | L5: Sam Lee | M5: Restore from backup | N5: N/A | O5: IT Glue > Configurations > FS01

Sheet 6 Network
A1: =IF(PreparedFor="","Network, Connectivity & External Dependencies","Network, Connectivity & External Dependencies | "&PreparedFor) -> Network, Connectivity & External Dependencies
A2: Circuits, WAN / VPN, DNS, domains, certificates, email routing, and telephony. These are the dependencies that quietly break every recovery when nobody knows the registrar login or the circuit ID. Row 5 (gray, italic) is an EXAMPLE — overwrite or delete it. Pink columns calculate automatically; don't type in them.
A3: Item | B3: Category | C3: Provider / Vendor | D3: Site | E3: Circuit / Account ID | F3: Bandwidth / Spec | G3: Public IP(s) / Records | H3: Support Phone | I3: Redundancy / Failover | J3: Renewal / Expiry Date | K3: Admin Access Location (vault reference — NOT the password) | L3: Notes
J4: Domains and certificates especially.
A5: Primary internet – HQ | B5: Internet circuit | C5: Spectrum Enterprise | D5: HQ | E5: CKT-0000000 | F5: 500/500 fiber | G5: 203.0.113.10/29 | H5: (800) 555-0100 | I5: LTE failover on firewall | K5: Vault: Network > ISP portal

Sheet 7 Backups
A1: =IF(PreparedFor="","Backup & Recovery Capability","Backup & Recovery Capability | "&PreparedFor) -> Backup & Recovery Capability
A2: One row per backup job or protected system — including SaaS (M365, Google Workspace, line-of-business SaaS). Pick the application in column B and the required RPO / RTO pull from tab 3 so gaps flag automatically. 'Frequency' means hours between restore points (nightly = 24). Row 5 (gray, italic) is an EXAMPLE — overwrite or delete it. Pink columns calculate automatically; don't type in them.
A3: Protected System / Data Set | B3: Supports Application (from tab 3) | C3: Required RPO (hrs) (calc) | D3: Required RTO (hrs) (calc) | E3: Backup Product | F3: Job / Policy Name | G3: Backup Method | H3: Frequency (hrs between restore points) | I3: RPO Gap? (calc) | J3: Retention (days) | K3: Primary Backup Target | L3: Offsite / Secondary Copy | M3: Immutable or Air-Gapped Copy? | N3: Backups Encrypted? | O3: MFA on Backup Console? | P3: Backup Admin Separate from Domain? | Q3: Failure Alerts Go To | R3: Last Successful Restore Test | S3: Restore Test Status (calc) | T3: Measured Restore Time (hrs) | U3: RTO Gap? (calc) | V3: Notes
B4: Dropdown pulls from tab 3. Leave blank for infrastructure-only jobs. | M4: Can an attacker with domain admin delete or encrypt it? If yes, the answer is No. | P4: Backup server / console not joined to, or authenticated by, the production domain. | R4: A verified restore, not a green job status. | T4: From the last real test. Blank = unknown.
A5: FS01 | C5: =IF(B5="","",IFERROR(IF(INDEX('3 Critical Apps'!$J$6:$J$105,MATCH(B5,'3 Critical Apps'!$A$6:$A$105,0))="","",INDEX('3 Critical Apps'!$J$6:$J$105,MATCH(B5,'3 Critical Apps'!$A$6:$A$105,0))),"")) | D5: =IF(B5="","",IFERROR(IF(INDEX('3 Critical Apps'!$I$6:$I$105,MATCH(B5,'3 Critical Apps'!$A$6:$A$105,0))="","",INDEX('3 Critical Apps'!$I$6:$I$105,MATCH(B5,'3 Critical Apps'!$A$6:$A$105,0))),"")) | E5: Veeam B&R 12 | F5: FS01-Nightly | G5: Image-based | H5: 24 | I5: =IF(OR(C5="",H5=""),"",IF(H5>C5,"GAP","OK")) | J5: 30 | K5: Local backup appliance | L5: Vendor cloud | M5: Yes | N5: Yes | O5: Yes | P5: No | Q5: helpdesk@ ; RMM ticket | S5: =IF(A5="","",IF(R5="","NEVER TESTED",IF(TODAY()-R5>RestoreTestMaxDays,"STALE","CURRENT"))) -> NEVER TESTED | T5: 6 | U5: =IF(OR(D5="",T5=""),"",IF(T5>D5,"GAP","OK"))
C6: =IF(B6="","",IFERROR(IF(INDEX('3 Critical Apps'!$J$6:$J$105,MATCH(B6,'3 Critical Apps'!$A$6:$A$105,0))="","",INDEX('3 Critical Apps'!$J$6:$J$105,MATCH(B6,'3 Critical Apps'!$A$6:$A$105,0))),"")) | D6: =IF(B6="","",IFERROR(IF(INDEX('3 Critical Apps'!$I$6:$I$105,MATCH(B6,'3 Critical Apps'!$A$6:$A$105,0))="","",INDEX('3 Critical Apps'!$I$6:$I$105,MATCH(B6,'3 Critical Apps'!$A$6:$A$105,0))),"")) | I6: =IF(OR(C6="",H6=""),"",IF(H6>C6,"GAP","OK")) | S6: =IF(A6="","",IF(R6="","NEVER TESTED",IF(TODAY()-R6>RestoreTestMaxDays,"STALE","CURRENT"))) | U6: =IF(OR(D6="",T6=""),"",IF(T6>D6,"GAP","OK"))
C7: =IF(B7="","",IFERROR(IF(INDEX('3 Critical Apps'!$J$6:$J$105,MATCH(B7,'3 Critical Apps'!$A$6:$A$105,0))="","",INDEX('3 Critical Apps'!$J$6:$J$105,MATCH(B7,'3 Critical Apps'!$A$6:$A$105,0))),"")) | D7: =IF(B7="","",IFERROR(IF(INDEX('3 Critical Apps'!$I$6:$I$105,MATCH(B7,'3 Critical Apps'!$A$6:$A$105,0))="","",INDEX('3 Critical Apps'!$I$6:$I$105,MATCH(B7,'3 Critical Apps'!$A$6:$A$105,0))),"")) | I7: =IF(OR(C7="",H7=""),"",IF(H7>C7,"GAP","OK")) | S7: =IF(A7="","",IF(R7="","NEVER TESTED",IF(TODAY()-R7>RestoreTestMaxDays,"STALE","CURRENT"))) | U7: =IF(OR(D7="",T7=""),"",IF(T7>D7,"GAP","OK"))
C8: =IF(B8="","",IFERROR(IF(INDEX('3 Critical Apps'!$J$6:$J$105,MATCH(B8,'3 Critical Apps'!$A$6:$A$105,0))="","",INDEX('3 Critical Apps'!$J$6:$J$105,MATCH(B8,'3 Critical Apps'!$A$6:$A$105,0))),"")) | D8: =IF(B8="","",IFERROR(IF(INDEX('3 Critical Apps'!$I$6:$I$105,MATCH(B8,'3 Critical Apps'!$A$6:$A$105,0))="","",INDEX('3 Critical Apps'!$I$6:$I$105,MATCH(B8,'3 Critical Apps'!$A$6:$A$105,0))),"")) | I8: =IF(OR(C8="",H8=""),"",IF(H8>C8,"GAP","OK")) | S8: =IF(A8="","",IF(R8="","NEVER TESTED",IF(TODAY()-R8>RestoreTestMaxDays,"STALE","CURRENT"))) | U8: =IF(OR(D8="",T8=""),"",IF(T8>D8,"GAP","OK"))
C9: =IF(B9="","",IFERROR(IF(INDEX('3 Critical Apps'!$J$6:$J$105,MATCH(B9,'3 Critical Apps'!$A$6:$A$105,0))="","",INDEX('3 Critical Apps'!$J$6:$J$105,MATCH(B9,'3 Critical Apps'!$A$6:$A$105,0))),"")) | D9: =IF(B9="","",IFERROR(IF(INDEX('3 Critical Apps'!$I$6:$I$105,MATCH(B9,'3 Critical Apps'!$A$6:$A$105,0))="","",INDEX('3 Critical Apps'!$I$6:$I$105,MATCH(B9,'3 Critical Apps'!$A$6:$A$105,0))),"")) | I9: =IF(OR(C9="",H9=""),"",IF(H9>C9,"GAP","OK")) | S9: =IF(A9="","",IF(R9="","NEVER TESTED",IF(TODAY()-R9>RestoreTestMaxDays,"STALE","CURRENT"))) | U9: =IF(OR(D9="",T9=""),"",IF(T9>D9,"GAP","OK"))
C10: =IF(B10="","",IFERROR(IF(INDEX('3 Critical Apps'!$J$6:$J$105,MATCH(B10,'3 Critical Apps'!$A$6:$A$105,0))="","",INDEX('3 Critical Apps'!$J$6:$J$105,MATCH(B10,'3 Critical Apps'!$A$6:$A$105,0))),"")) | D10: =IF(B10="","",IFERROR(IF(INDEX('3 Critical Apps'!$I$6:$I$105,MATCH(B10,'3 Critical Apps'!$A$6:$A$105,0))="","",INDEX('3 Critical Apps'!$I$6:$I$105,MATCH(B10,'3 Critical Apps'!$A$6:$A$105,0))),"")) | I10: =IF(OR(C10="",H10=""),"",IF(H10>C10,"GAP","OK")) | S10: =IF(A10="","",IF(R10="","NEVER TESTED",IF(TODAY()-R10>RestoreTestMaxDays,"STALE","CURRENT"))) | U10: =IF(OR(D10="",T10=""),"",IF(T10>D10,"GAP","OK"))
C11: =IF(B11="","",IFERROR(IF(INDEX('3 Critical Apps'!$J$6:$J$105,MATCH(B11,'3 Critical Apps'!$A$6:$A$105,0))="","",INDEX('3 Critical Apps'!$J$6:$J$105,MATCH(B11,'3 Critical Apps'!$A$6:$A$105,0))),"")) | D11: =IF(B11="","",IFERROR(IF(INDEX('3 Critical Apps'!$I$6:$I$105,MATCH(B11,'3 Critical Apps'!$A$6:$A$105,0))="","",INDEX('3 Critical Apps'!$I$6:$I$105,MATCH(B11,'3 Critical Apps'!$A$6:$A$105,0))),"")) | I11: =IF(OR(C11="",H11=""),"",IF(H11>C11,"GAP","OK")) | S11: =IF(A11="","",IF(R11="","NEVER TESTED",IF(TODAY()-R11>RestoreTestMaxDays,"STALE","CURRENT"))) | U11: =IF(OR(D11="",T11=""),"",IF(T11>D11,"GAP","OK"))
C12: =IF(B12="","",IFERROR(IF(INDEX('3 Critical Apps'!$J$6:$J$105,MATCH(B12,'3 Critical Apps'!$A$6:$A$105,0))="","",INDEX('3 Critical Apps'!$J$6:$J$105,MATCH(B12,'3 Critical Apps'!$A$6:$A$105,0))),"")) | D12: =IF(B12="","",IFERROR(IF(INDEX('3 Critical Apps'!$I$6:$I$105,MATCH(B12,'3 Critical Apps'!$A$6:$A$105,0))="","",INDEX('3 Critical Apps'!$I$6:$I$105,MATCH(B12,'3 Critical Apps'!$A$6:$A$105,0))),"")) | I12: =IF(OR(C12="",H12=""),"",IF(H12>C12,"GAP","OK")) | S12: =IF(A12="","",IF(R12="","NEVER TESTED",IF(TODAY()-R12>RestoreTestMaxDays,"STALE","CURRENT"))) | U12: =IF(OR(D12="",T12=""),"",IF(T12>D12,"GAP","OK"))
C13: =IF(B13="","",IFERROR(IF(INDEX('3 Critical Apps'!$J$6:$J$105,MATCH(B13,'3 Critical Apps'!$A$6:$A$105,0))="","",INDEX('3 Critical Apps'!$J$6:$J$105,MATCH(B13,'3 Critical Apps'!$A$6:$A$105,0))),"")) | D13: =IF(B13="","",IFERROR(IF(INDEX('3 Critical Apps'!$I$6:$I$105,MATCH(B13,'3 Critical Apps'!$A$6:$A$105,0))="","",INDEX('3 Critical Apps'!$I$6:$I$105,MATCH(B13,'3 Critical Apps'!$A$6:$A$105,0))),"")) | I13: =IF(OR(C13="",H13=""),"",IF(H13>C13,"GAP","OK")) | S13: =IF(A13="","",IF(R13="","NEVER TESTED",IF(TODAY()-R13>RestoreTestMaxDays,"STALE","CURRENT"))) | U13: =IF(OR(D13="",T13=""),"",IF(T13>D13,"GAP","OK"))
C14: =IF(B14="","",IFERROR(IF(INDEX('3 Critical Apps'!$J$6:$J$105,MATCH(B14,'3 Critical Apps'!$A$6:$A$105,0))="","",INDEX('3 Critical Apps'!$J$6:$J$105,MATCH(B14,'3 Critical Apps'!$A$6:$A$105,0))),"")) | D14: =IF(B14="","",IFERROR(IF(INDEX('3 Critical Apps'!$I$6:$I$105,MATCH(B14,'3 Critical Apps'!$A$6:$A$105,0))="","",INDEX('3 Critical Apps'!$I$6:$I$105,MATCH(B14,'3 Critical Apps'!$A$6:$A$105,0))),"")) | I14: =IF(OR(C14="",H14=""),"",IF(H14>C14,"GAP","OK")) | S14: =IF(A14="","",IF(R14="","NEVER TESTED",IF(TODAY()-R14>RestoreTestMaxDays,"STALE","CURRENT"))) | U14: =IF(OR(D14="",T14=""),"",IF(T14>D14,"GAP","OK"))
C15: =IF(B15="","",IFERROR(IF(INDEX('3 Critical Apps'!$J$6:$J$105,MATCH(B15,'3 Critical Apps'!$A$6:$A$105,0))="","",INDEX('3 Critical Apps'!$J$6:$J$105,MATCH(B15,'3 Critical Apps'!$A$6:$A$105,0))),"")) | D15: =IF(B15="","",IFERROR(IF(INDEX('3 Critical Apps'!$I$6:$I$105,MATCH(B15,'3 Critical Apps'!$A$6:$A$105,0))="","",INDEX('3 Critical Apps'!$I$6:$I$105,MATCH(B15,'3 Critical Apps'!$A$6:$A$105,0))),"")) | I15: =IF(OR(C15="",H15=""),"",IF(H15>C15,"GAP","OK")) | S15: =IF(A15="","",IF(R15="","NEVER TESTED",IF(TODAY()-R15>RestoreTestMaxDays,"STALE","CURRENT"))) | U15: =IF(OR(D15="",T15=""),"",IF(T15>D15,"GAP","OK"))
C16: =IF(B16="","",IFERROR(IF(INDEX('3 Critical Apps'!$J$6:$J$105,MATCH(B16,'3 Critical Apps'!$A$6:$A$105,0))="","",INDEX('3 Critical Apps'!$J$6:$J$105,MATCH(B16,'3 Critical Apps'!$A$6:$A$105,0))),"")) | D16: =IF(B16="","",IFERROR(IF(INDEX('3 Critical Apps'!$I$6:$I$105,MATCH(B16,'3 Critical Apps'!$A$6:$A$105,0))="","",INDEX('3 Critical Apps'!$I$6:$I$105,MATCH(B16,'3 Critical Apps'!$A$6:$A$105,0))),"")) | I16: =IF(OR(C16="",H16=""),"",IF(H16>C16,"GAP","OK")) | S16: =IF(A16="","",IF(R16="","NEVER TESTED",IF(TODAY()-R16>RestoreTestMaxDays,"STALE","CURRENT"))) | U16: =IF(OR(D16="",T16=""),"",IF(T16>D16,"GAP","OK"))
C17: =IF(B17="","",IFERROR(IF(INDEX('3 Critical Apps'!$J$6:$J$105,MATCH(B17,'3 Critical Apps'!$A$6:$A$105,0))="","",INDEX('3 Critical Apps'!$J$6:$J$105,MATCH(B17,'3 Critical Apps'!$A$6:$A$105,0))),"")) | D17: =IF(B17="","",IFERROR(IF(INDEX('3 Critical Apps'!$I$6:$I$105,MATCH(B17,'3 Critical Apps'!$A$6:$A$105,0))="","",INDEX('3 Critical Apps'!$I$6:$I$105,MATCH(B17,'3 Critical Apps'!$A$6:$A$105,0))),"")) | I17: =IF(OR(C17="",H17=""),"",IF(H17>C17,"GAP","OK")) | S17: =IF(A17="","",IF(R17="","NEVER TESTED",IF(TODAY()-R17>RestoreTestMaxDays,"STALE","CURRENT"))) | U17: =IF(OR(D17="",T17=""),"",IF(T17>D17,"GAP","OK"))
... C105: =IF(B105="","",IFERROR(IF(INDEX('3 Critical Apps'!$J$6:$J$105,MATCH(B105,'3 Critical Apps'!$A$6:$A$105,0))="","",INDEX('3 Critical Apps'!$J$6:$J$105,MATCH(B105,'3 Critical Apps'!$A$6:$A$105,0))),"")) | D105: =IF(B105="","",IFERROR(IF(INDEX('3 Critical Apps'!$I$6:$I$105,MATCH(B105,'3 Critical Apps'!$A$6:$A$105,0))="","",INDEX('3 Critical Apps'!$I$6:$I$105,MATCH(B105,'3 Critical Apps'!$A$6:$A$105,0))),"")) | I105: =IF(OR(C105="",H105=""),"",IF(H105>C105,"GAP","OK")) | S105: =IF(A105="","",IF(R105="","NEVER TESTED",IF(TODAY()-R105>RestoreTestMaxDays,"STALE","CURRENT"))) | U105: =IF(OR(D105="",T105=""),"",IF(T105>D105,"GAP","OK"))

Sheet 8 Break-Glass Access
A1: =IF(PreparedFor="","Privileged & Break-Glass Access","Privileged & Break-Glass Access | "&PreparedFor) -> Privileged & Break-Glass Access
A2: Accounts you will need when things are broken. DO NOT RECORD PASSWORDS, SECRETS, OR MFA SEEDS IN THIS WORKBOOK — record where they are stored and who can reach them. Key question: can you get to them if the domain, IdP, and password manager are all down? Row 5 (gray, italic) is an EXAMPLE — overwrite or delete it. Pink columns calculate automatically; don't type in them.
A3: Account / Credential (name only) | B3: System | C3: Account Type | D3: Purpose | E3: MFA Enabled? | F3: MFA Method / Token Location | G3: Credential Storage Method | H3: Storage Location Detail | I3: Who Can Access (min. 2 people) | J3: Reachable if Domain / IdP / Network Down? | K3: Last Verified Working | L3: Notes
A5: breakglass01@tenant.onmicrosoft.com | B5: Microsoft 365 / Entra ID | C5: Break-glass / emergency | D5: Tenant recovery if SSO / Conditional Access fails | E5: Yes | F5: FIDO2 key in HQ safe | G5: Sealed envelope in safe | H5: HQ safe, CFO office | I5: CFO; IT Director | J5: Yes

Sheet 9 Internal Contacts
A1: =IF(PreparedFor="","Internal Contacts & Recovery Team","Internal Contacts & Recovery Team | "&PreparedFor) -> Internal Contacts & Recovery Team
A2: Everyone with a role in a disaster — leadership, IT, department leads, facilities. Capture contact methods that work when corporate email and phones are down. Print or export this tab and keep an offline copy. Row 5 (gray, italic) is an EXAMPLE — overwrite or delete it. Pink columns calculate automatically; don't type in them.
A3: Name | B3: Title | C3: Department | D3: DR Role | E3: Systems / Areas of Expertise | F3: Mobile Phone | G3: Secondary Phone | H3: Work Email | I3: Personal / Out-of-Band Email or Chat | J3: Home Region / Commute | K3: Backup / Alternate Person | L3: Authority to Declare Disaster? | M3: Emergency Spending Authority? | N3: Spending Limit ($) | O3: Notes
I4: Reachable if corporate email is down. | J4: Matters for regional events (weather, site loss).
A5: Jane Doe | B5: Controller | C5: Finance | D5: Business Liaison | E5: Paylocity, AP/AR processes | F5: (502) 555-0142 | H5: jdoe@example.org | I5: Signal: same mobile | J5: Louisville, 20 min | K5: Tom Ray | L5: No | M5: Yes | N5: 10000

Sheet 10 Vendors
A1: =IF(PreparedFor="","Vendors & Third Parties","Vendors & Third Parties | "&PreparedFor) -> Vendors & Third Parties
A2: Every outside party you'd call during recovery: MSP / MSSP, ISPs, SaaS and software vendors, hardware support, backup provider, cyber insurer, breach counsel, IR firm, utilities. Account numbers and authorized callers are what slow you down at 2 a.m. Row 5 (gray, italic) is an EXAMPLE — overwrite or delete it. Pink columns calculate automatically; don't type in them.
A3: Vendor / Provider | B3: Category | C3: Services / Products Provided | D3: Supports Apps / Systems | E3: Criticality | F3: Account / Customer # | G3: Support Phone | H3: Support Portal / Email | I3: Support Hours | J3: Contracted SLA / Response Time | K3: Account Manager / Escalation Contact | L3: Escalation Phone / Email | M3: Contract Expiry | N3: Vendor's Own DR / Resiliency Attested? | O3: Authorized Callers on Account | P3: Notes
M4: Red = expired, amber = within warning window. | N4: SOC 2, SLA credits, documented DR — their outage is your outage. | O4: Who the vendor will actually talk to.
A5: Paylocity | B5: Cloud / SaaS provider | C5: Payroll & HR SaaS | D5: Paylocity | E5: High | F5: Client ID 00000 | G5: (800) 555-0199 | H5: support.example.com | I5: Business hours only | J5: 4-hr response, P1 | K5: Chris Patel, CSM | L5: cpatel@example.com | N5: Yes | O5: Jane Doe; Sam Lee

Sheet 11 Recovery Sites
A1: =IF(PreparedFor="","Locations & Recovery Resources","Locations & Recovery Resources | "&PreparedFor) -> Locations & Recovery Resources
A2: Where people and systems go if a site is lost, and what physical resources exist for recovery — alternate offices, colo / cloud recovery regions, work-from-home capacity, spare hardware, and emergency procurement sources. Row 5 (gray, italic) is an EXAMPLE — overwrite or delete it. Pink columns calculate automatically; don't type in them.
A3: Location / Resource | B3: Type | C3: Address / Region | D3: Capacity (users or systems) | E3: Time to Operational (hrs) | F3: Contact / Owner | G3: Access Requirements (keys, badges, approvals) | H3: Network / Power / Generator Available? | I3: Agreement in Place? | J3: Notes
A5: Branch office – East | B5: Alternate work site | C5: 123 Main St, Lexington KY | D5: 15 seats | E5: 8 | F5: Office manager, (859) 555-0110 | G5: Badge access for IT; keys with office mgr | H5: Yes | I5: N/A

Sheet 12 Communications
A1: =IF(PreparedFor="","Crisis Communications Plan","Crisis Communications Plan | "&PreparedFor) -> Crisis Communications Plan
A2: Who gets told what, by whom, and how — assuming corporate email and Teams may be the thing that's down. Include employees, leadership, customers, regulators, insurer, media, and key vendors. Row 5 (gray, italic) is an EXAMPLE — overwrite or delete it. Pink columns calculate automatically; don't type in them.
A3: Stakeholder Group | B3: Who Notifies (role) | C3: Approval Required From | D3: Timing / Trigger | E3: Primary Method | F3: Backup / Out-of-Band Method | G3: Contact List Location | H3: Message Template Location | I3: Notes
G4: Must be reachable offline.
A5: All employees | B5: Communications Lead | C5: Incident Commander | D5: Within 1 hr of declaration; every 4 hrs | E5: SMS / mass notification | F5: Phone tree | G5: Tab 9 printout; mass-notify platform | H5: Printed DR binder, section 4

Sheet 13 Gaps & Actions
A1: =IF(PreparedFor="","Gaps, Open Questions & Action Items","Gaps, Open Questions & Action Items | "&PreparedFor) -> Gaps, Open Questions & Action Items
A2: Log anything you couldn't answer, didn't like the answer to, or flagged red elsewhere. This list becomes the remediation roadmap that accompanies the DR plan. Row 5 (gray, italic) is an EXAMPLE — overwrite or delete it. Pink columns calculate automatically; don't type in them.
A3: ID | B3: Tab / Area | C3: Finding / Gap / Open Question | D3: Risk Level | E3: Recommended Action | F3: Owner | G3: Target Date | H3: Status | I3: Notes
A5: G-001 | B5: 7 Backups | C5: Backup console authenticates to production AD; ransomware could delete backups | D5: Critical | E5: Move backup server to workgroup, enable MFA, add immutable cloud copy | F5: Sam Lee | H5: Open

Sheet Lists
A1: Thresholds (edit to match your organization) | D1: Dropdown values (add items to the end of a list to extend it)
A2: Tier 1 = max tolerable downtime up to (hours) | B2: 4 | D2: YesNo | E2: Impact | F2: Tier | G2: Hosting | H2: AuthMethod | I2: Classification | J2: Regulatory | K2: AssetType | L2: RecoveryMethod | M2: NetCategory | N2: BackupMethod | O2: BackupTarget | P2: AcctType | Q2: CredStorage | R2: DRRole | S2: VendorCat | T2: SupportHours | U2: SiteType | V2: CommMethod | W2: Status
A3: Tier 2 = up to (hours) | B3: 24 | D3: Yes | E3: Critical | F3: Tier 1 | G3: On-premises | H3: Active Directory | I3: Public | J3: None | K3: Physical server | L3: Restore from backup | M3: Internet circuit | N3: Image-based | O3: Local backup appliance | P3: Break-glass / emergency | Q3: Password manager (cloud) | R3: Executive Sponsor | S3: MSP / MSSP | T3: 24x7x365 | U3: Primary site | V3: Phone tree | W3: Open
A4: Tier 3 = up to (hours); anything longer is Tier 4 | B4: 72 | D4: No | E4: High | F4: Tier 2 | G4: Private cloud / colo | H4: Entra ID / SSO | I4: Internal | J4: HIPAA | K4: Virtual machine | L4: Failover to replica | M4: MPLS / private WAN | N4: File-level | O4: NAS / SAN | P4: Global / domain admin | Q4: Password manager (offline / local vault) | R4: Incident Commander | S4: ISP / carrier | T4: Business hours + on-call | U4: Alternate work site | V4: SMS / mass notification | W4: In Progress
A5: Restore test is STALE after (days) | B5: 365 | D5: Unknown | E5: Medium | F5: Tier 3 | G5: IaaS (Azure / AWS / GCP) | H5: Other IdP (Okta, Duo, etc.) | I5: Confidential | J5: PCI DSS | K5: Hypervisor host | L5: Rebuild from documentation | M5: SD-WAN | N5: Application-aware (SQL, etc.) | O5: Vendor cloud | P5: Hypervisor root / admin | Q5: Sealed envelope in safe | R5: Deputy Incident Commander | S5: Cloud / SaaS provider | T5: Business hours only | U5: Recovery datacenter / colo | V5: Email | W5: Resolved
A6: Warn on expiring contracts / warranties / domains within (days) | B6: 90 | D6: N/A | E6: Low | F6: Tier 4 | G6: SaaS | H6: Local application accounts | I6: Restricted / Regulated | J6: CMMC / DFARS (CUI) | K6: Storage (SAN / NAS) | L6: Redeploy from template / IaC | M6: Site-to-site VPN | N6: SaaS-to-SaaS (M365, Google) | O6: Customer-owned cloud storage | P6: Backup console admin | Q6: Hardware token / key | R6: Technical Recovery Lead | S6: Hardware vendor | T6: Best effort | U6: Cloud recovery region | V6: Teams / Slack | W6: Accepted Risk
G7: Hybrid | H7: Unknown | J7: FERPA | K7: Firewall | L7: Vendor-managed recovery | M7: Remote access VPN / ZTNA | N7: Snapshot | O7: Tape | P7: Firewall / network admin | Q7: Split knowledge (two people) | R7: Communications Lead | S7: Software vendor | T7: Unknown | U7: Work-from-home | V7: Out-of-band chat (Signal, etc.)
J8: CJIS | K8: Switch | L8: Replace hardware | M8: Domain registrar | N8: Replication | O8: Removable media | P8: Registrar / DNS portal | Q8: Unknown | R8: Business Liaison | S8: Backup / DR provider | U8: Spare hardware cache | V8: Status page / website
J9: GLBA | K9: Router / SD-WAN | L9: Unknown | M9: Public DNS hosting | N9: Config export | O9: None | P9: Cloud subscription owner | R9: Legal / Compliance | S9: Cyber insurance carrier | U9: Emergency procurement source | V9: Press release / media
J10: SOX | K10: Wireless controller / AP | M10: Internal DNS / DHCP | N10: None | O10: Other | P10: Service account | R10: Vendor Coordinator | S10: Breach counsel | U10: Other | V10: In person
J11: State privacy law | K11: Cloud tenant / subscription | M11: SSL / TLS certificate | P11: Vendor portal | R11: Recovery Team Member | S11: Incident response firm
J12: Multiple | K12: Critical workstation | M12: Email routing / MX / filtering | P12: Other | R12: None | S12: Utility / facilities
J13: Other | K13: Other | M13: Telephony / VoIP | S13: Other
M14: Other
