Workbook

Sheet Start Here
A1: Client Relationship Health Assessment | E1: [ Your logo ]
A2: A quarterly, evidence-based read on the health of each client relationship.
A5: INTERNAL USE ONLY
A6: This assessment rates the client's behavior and our relationship with them. Do not share it with the client, include it in client-facing reports, or attach it to a QBR deck. Use the findings to prepare for the QBR; present the resulting actions, not the ratings.
A8: Purpose
A9: Technical assessments measure the client's environment. This one measures the relationship: governance, service experience, feedback, commercial health, strategic alignment, and known risk triggers.
A10: Most items are scored from data in your PSA, CSAT tool, and accounting system so the account owner isn't grading their own work. Judgment items require evidence.
A12: When to run it
A13: Quarterly, about two weeks before each QBR.
A14: Within 30 days of a change in the client's primary contact or decision-maker.
A15: 120 days before agreement renewal.
A16: After a major outage or security incident.
A18: How to complete it
... A43: Legend
A44: Input | B44: Yellow cells with blue text: enter or edit these.
A45: Calculated | B45: Grey cells: formulas. Don't overwrite.
A46: Example | B46: Grey italic: example values showing the expected format. Not used in scoring.
A48: Tabs
A49: Client Info | B49: Client, agreement, and margin details.
A50: Data Inputs | B50: Objective metrics from your PSA, CSAT tool, and accounting system.
A51: Assessment | B51: 29 items across six dimensions, with outcomes, evidence, and recommended plays.
A52: Summary | B52: Score, rating, alerts, Health x Profitability, and the prioritized action list.
A53: Thresholds | B53: Tunable thresholds and scoring settings.
A55: Lifecycle Manager X version
A56: This assessment is also available as a ScalePad Lifecycle Manager X template, along with help aligning the resulting initiatives to your service offerings. Contact MSP Culture:
A57: https://github.com/MSPCulture/msp-culture
A59: Terms of use
A60: Free to use and modify within your organization, including with your clients.
A61: Do not resell this workbook or redistribute it, original or modified, as your own product.
A62: Provided as-is, with no warranty. You are responsible for how you use the results.
A64: Version 1.0 | October 2026
A65: Powered by MSP Culture

Sheet Client Info
A1: Client Information
A2: Complete the yellow cells. Example column shows the expected format.
A4: Field | B4: Value | C4: Example | D4: Notes
A5: Assessing MSP | C5: Your MSP name | D5: Appears on the Summary tab.
A6: Client name | C6: Riverbend Dental Group
A7: Assessment date | C7: 46310 | D7: All 'last 90 days' and 'last 12 months' data should be pulled as of this date.
A8: Assessor | C8: J. Smith, vCIO | D8: Should not be the only person who manages the account day-to-day.
A9: Account manager | C9: R. Lee
A10: Client primary contact | C10: Office Manager
A11: Client executive sponsor / decision-maker | C11: Practice Owner | D11: The person who signs the renewal.
A12: Agreement type | C12: Managed services - all-inclusive
A13: Agreement start date | C13: 44986
A14: Next renewal date | C14: 46446
A15: Days to renewal | B15: =IF(OR(B14="",B7=""),"",B14-B7) | D15: Calculated. 120 days or fewer triggers a renewal warning on the Summary.
A16: Active users (current) | C16: 48 | D16: Used to normalize ticket volume.
A17: Contracted QBRs per year | C17: 4 | D17: Per the agreement or your service standard.
A18: Payment terms (days) | C18: 30
A19: Agreement gross margin % (trailing 12 months) | C19: 0.42 | D19: From your PSA agreement profitability report.
A20: Target agreement gross margin % | C20: 0.5 | D20: Your internal target for this agreement type.
A21: Previous assessment score | C21: 78 | D21: Leave blank for the first assessment.
A22: Previous assessment date | C22: 46217

Sheet Data Inputs
A1: Data Inputs
A2: Pull these figures from your PSA, CSAT tool, and accounting system as of the assessment date. Calculated metrics feed the Assessment tab.
A4: ID | B4: Assessment item | C4: Input | D4: Value | E4: Example | F4: Where to find it | G4: Calculated metric
A5: G1 | B5: QBR completion | C5: QBRs held in the last 12 months | E5: 3 | F5: PSA calendar, QBR log, or Lifecycle Manager meeting history. | G5: =IF(OR($D$5="",'Client Info'!$B$17=""),"",IF('Client Info'!$B$17=0,"",$D$5/'Client Info'!$B$17))
A6: G2 | B6: Time since last QBR | C6: Date of most recent QBR actually held | E6: 46254 | F6: PSA calendar or QBR log. | G6: =IF(OR($D$6="",'Client Info'!$B$7=""),"",ROUND(('Client Info'!$B$7-$D$6)/30.44,1))
A7: G5 | B7: QBR commitments delivered | C7: Action items we committed to at the last QBR | E7: 6 | F7: QBR notes / action log. | G7: =IF(OR($D$7="",$D$8=""),"",IF($D$7=0,"none",$D$8/$D$7))
A8: G5 | B8: QBR commitments delivered | C8: Of those, completed by the agreed date | E8: 5 | F8: QBR notes / PSA project or ticket status.
A9: G6 | B9: Relationship breadth | C9: Client contacts with an active, direct relationship with us | E9: 2 | F9: Account manager / vCIO judgment; CRM contact activity. | G9: =IF($D$9="","",$D$9)
A10: S1 | B10: Ticket volume vs baseline | C10: Tickets opened in the last 90 days | E10: 61 | F10: PSA ticket report, company filter, date opened. | G10: =IF(OR($D$10="",$D$11="",'Client Info'!$B$16=""),"",IF(OR($D$11=0,'Client Info'!$B$16=0),"",($D$10/3/'Client Info'!$B$16)/($D$11/12/IF($D$12="",'Client Info'!$B$16,$D$12))))
A11: S1 | B11: Ticket volume vs baseline | C11: Tickets opened in the last 12 months | E11: 291 | F11: Same report, last 12 months (includes the last 90 days).
A12: S1 | B12: Ticket volume vs baseline | C12: Average users over the last 12 months (optional) | E12: 45 | F12: Leave blank to use current user count.
A13: S2 | B13: Service desk bypass | C13: Requests that bypassed the service desk in the last 90 days | E13: 4 | F13: Tickets created by techs on the client's behalf from direct texts/calls; ask the team. | G13: =IF(OR($D$13="",$D$10=""),"",IF($D$10=0,"",$D$13/$D$10))
A14: S3 | B14: Reopened / repeat tickets | C14: Tickets reopened or repeating a prior issue, last 90 days | E14: 3 | F14: PSA reopen count or tickets linked to a prior ticket. | G14: =IF(OR($D$14="",$D$10=""),"",IF($D$10=0,"",$D$14/$D$10))
A15: S4 | B15: SLA attainment | C15: SLA attainment %, last 90 days | E15: 0.93 | F15: PSA SLA report for the company. | G15: =IF($D$15="","",$D$15)
A16: S5 | B16: Assignment stability | C16: Changes to assigned primary tech / TAM in the last 12 months | E16: 1 | F16: Team assignment history. | G16: =IF($D$16="","",$D$16)
A17: F1 | B17: CSAT response rate | C17: CSAT surveys sent, last 90 days | E17: 55 | F17: CSAT tool (e.g., SmileBack, Crewhu) or PSA survey report. | G17: =IF(OR($D$17="",$D$18=""),"",IF($D$17=0,"",$D$18/$D$17))
A18: F1 | B18: CSAT response rate | C18: CSAT responses received, last 90 days | E18: 7 | F18: Same report.
A19: F2 | B19: CSAT positive rate | C19: Positive responses, last 90 days | E19: 6 | F19: Same report. | G19: =IF(OR($D$19="",$D$18=""),"",IF($D$18=0,"",$D$19/$D$18))
A20: F3 | B20: Negative CSAT follow-up | C20: Negative responses, last 90 days | E20: 1 | F20: Same report. | G20: =IF($D$20="","",IF($D$20=0,"none",IF($D$21="","",$D$21/$D$20)))
A21: F3 | B21: Negative CSAT follow-up | C21: Negative responses followed up by a person within 2 business days | E21: 1 | F21: Ticket notes / CSAT tool follow-up log.
A22: C1 | B22: Payment timeliness | C22: Average days to pay, last 90 days | E22: 38 | F22: Accounting system or PSA invoice aging. | G22: =IF(OR($D$22="",'Client Info'!$B$18=""),"",$D$22-'Client Info'!$B$18)
A23: C1 | B23: Payment timeliness | C23: Average days to pay, prior 90 days | E23: 31 | F23: Same report, prior period.
A24: C2 | B24: Proposal approval rate | C24: Proposals / initiatives presented, last 12 months | E24: 5 | F24: PSA opportunities, quoting tool, or Lifecycle Manager initiatives. | G24: =IF(OR($D$24="",$D$25=""),"",IF($D$24=0,"none",$D$25/$D$24))
A25: C2 | B25: Proposal approval rate | C25: Of those, approved | E25: 2 | F25: Same source.
A26: C3 | B26: Stalled proposals | C26: Proposals open more than 60 days without a decision | E26: 2 | F26: Quoting tool / PSA opportunities. | G26: =IF($D$26="","",$D$26)

Sheet Assessment
A1: Relationship Health Assessment
A2: Data items score automatically from the Data Inputs tab. Score judgment items in 'Assessor outcome'. An assessor outcome overrides the suggestion and requires evidence.
A4: ID | B4: Dimension | C4: Question | D4: Why it matters | E4: Basis | F4: Critical | G4: Weight | H4: Satisfactory | I4: Needs Attention | J4: At Risk | K4: Measured value | L4: Suggested outcome | M4: Assessor outcome | N4: Final outcome | O4: Evidence / notes | P4: Flag | Q4: Recommended play (if not Satisfactory) | R4: Points | S4: Action order
A5: G1 | B5: Governance & Engagement | C5: Are QBRs being held at the contracted cadence? | D5: QBRs are the primary governance mechanism. A slipping cadence is usually the first visible sign of disengagement, on either side. | E5: Data | F5: N | G5: 2 | H5: ="At least "&TEXT(Thresholds!$D$5,"0%")&" of contracted QBRs held in the last 12 months" -> At least 90% of contracted QBRs held in the last 12 months | I5: ="Between "&TEXT(Thresholds!$E$5,"0%")&" and "&TEXT(Thresholds!$D$5,"0%")&" held" -> Between 60% and 90% held | J5: ="Fewer than "&TEXT(Thresholds!$E$5,"0%")&" held" -> Fewer than 60% held | K5: ='Data Inputs'!$G$5 | L5: =IF('Data Inputs'!$G$5="","",IF('Data Inputs'!$G$5>=Thresholds!$D$5,"Satisfactory",IF('Data Inputs'!$G$5<Thresholds!$E$5,"At Risk","Needs Attention"))) | N5: =IF(M5<>"",M5,L5) | P5: =IF(N5="","Not scored",IF(AND(L5<>"",M5<>"",M5<>L5,O5=""),"Override: add evidence",IF(AND(E5<>"Data",N5<>"Satisfactory",O5=""),"Add evidence",""))) -> Not scored | Q5: Get the next QBR on the calendar this week. If the client keeps rescheduling, ask directly whether the format is serving them, then shorten or restructure it. | R5: =IF(N5="Satisfactory",Thresholds!$D$25,IF(N5="Needs Attention",Thresholds!$D$26,IF(N5="At Risk",Thresholds!$D$27,0))) -> 0 | S5: =IF(N5="At Risk",COUNTIF($N$5:N5,"At Risk"),IF(N5="Needs Attention",COUNTIF($N$5:$N$33,"At Risk")+COUNTIF($N$5:N5,"Needs Attention"),""))
A6: G2 | B6: Governance & Engagement | C6: How recently was a QBR actually held? | D6: Cadence on paper means nothing if the last real conversation was two quarters ago. | E6: Data | F6: N | G6: 2 | H6: ="Within the last "&TEXT(Thresholds!$D$6,"0")&" months" -> Within the last 4 months | I6: ="Between "&TEXT(Thresholds!$D$6,"0")&" and "&TEXT(Thresholds!$E$6,"0")&" months ago" -> Between 4 and 6 months ago | J6: ="More than "&TEXT(Thresholds!$E$6,"0")&" months ago, or never" -> More than 6 months ago, or never | K6: ='Data Inputs'!$G$6 | L6: =IF('Data Inputs'!$G$6="","",IF('Data Inputs'!$G$6<=Thresholds!$D$6,"Satisfactory",IF('Data Inputs'!$G$6>Thresholds!$E$6,"At Risk","Needs Attention"))) | N6: =IF(M6<>"",M6,L6) | P6: =IF(N6="","Not scored",IF(AND(L6<>"",M6<>"",M6<>L6,O6=""),"Override: add evidence",IF(AND(E6<>"Data",N6<>"Satisfactory",O6=""),"Add evidence",""))) -> Not scored | Q6: Schedule now. If it has been more than six months, request a short executive check-in rather than a full QBR to re-establish contact first. | R6: =IF(N6="Satisfactory",Thresholds!$D$25,IF(N6="Needs Attention",Thresholds!$D$26,IF(N6="At Risk",Thresholds!$D$27,0))) -> 0 | S6: =IF(N6="At Risk",COUNTIF($N$5:N6,"At Risk"),IF(N6="Needs Attention",COUNTIF($N$5:$N$33,"At Risk")+COUNTIF($N$5:N6,"Needs Attention"),""))
A7: G3 | B7: Governance & Engagement | C7: Does the client's decision-maker attend and engage in QBRs? | D7: If the person who signs the renewal isn't in the room, the QBR is informing the wrong audience. | E7: Judgment | F7: N | G7: 3 | H7: Decision-maker attended the most recent QBR and actively participated in decisions. | I7: Decision-maker attends inconsistently, or delegates decisions to an office or operations contact. | J7: Decision-maker has not attended a QBR in 6+ months, or we are not certain who the decision-maker is. | K7: n/a | N7: =IF(M7<>"",M7,L7) -> 0 | P7: =IF(N7="","Not scored",IF(AND(L7<>"",M7<>"",M7<>L7,O7=""),"Override: add evidence",IF(AND(E7<>"Data",N7<>"Satisfactory",O7=""),"Add evidence",""))) -> Not scored | Q7: Request 30 minutes directly with the decision-maker. Rebuild the QBR agenda around business outcomes they own, not ticket statistics. | R7: =IF(N7="Satisfactory",Thresholds!$D$25,IF(N7="Needs Attention",Thresholds!$D$26,IF(N7="At Risk",Thresholds!$D$27,0))) -> 0 | S7: =IF(N7="At Risk",COUNTIF($N$5:N7,"At Risk"),IF(N7="Needs Attention",COUNTIF($N$5:$N$33,"At Risk")+COUNTIF($N$5:N7,"Needs Attention"),""))
A8: G4 | B8: Governance & Engagement | C8: Has the client's primary contact or executive sponsor changed, and do we have a relationship with the current one? | D8: Champion turnover is one of the strongest leading indicators of churn. The new person didn't choose us and owes us nothing. | E8: Judgment | F8: Y | G8: 3 | H8: Same primary contact and sponsor for 12+ months, with an established working relationship. | I8: A change occurred in the last 12 months, and we have met and briefed the new contact. | J8: A change occurred and we have not established a relationship with the replacement, or the role is vacant. | K8: n/a | N8: =IF(M8<>"",M8,L8) -> 0 | P8: =IF(N8="","Not scored",IF(AND(L8<>"",M8<>"",M8<>L8,O8=""),"Override: add evidence",IF(AND(E8<>"Data",N8<>"Satisfactory",O8=""),"Add evidence",""))) -> Not scored | Q8: Treat it as a re-sale. Schedule an introduction meeting within two weeks, walk through what we deliver and the value delivered to date, and re-confirm priorities. | R8: =IF(N8="Satisfactory",Thresholds!$D$25,IF(N8="Needs Attention",Thresholds!$D$26,IF(N8="At Risk",Thresholds!$D$27,0))) -> 0 | S8: =IF(N8="At Risk",COUNTIF($N$5:N8,"At Risk"),IF(N8="Needs Attention",COUNTIF($N$5:$N$33,"At Risk")+COUNTIF($N$5:N8,"Needs Attention"),""))
A9: G5 | B9: Governance & Engagement | C9: Did we complete the action items we committed to at the last QBR? | D9: This measures our side of the relationship. Missed commitments erode credibility faster than any single ticket. | E9: Data | F9: N | G9: 2 | H9: ="At least "&TEXT(Thresholds!$D$7,"0%")&" completed by the agreed date" -> At least 90% completed by the agreed date | I9: ="Between "&TEXT(Thresholds!$E$7,"0%")&" and "&TEXT(Thresholds!$D$7,"0%")&" completed, or no action items were recorded" -> Between 70% and 90% completed, or no action items were recorded | J9: ="Fewer than "&TEXT(Thresholds!$E$7,"0%")&" completed" -> Fewer than 70% completed | K9: ='Data Inputs'!$G$7 | L9: =IF('Data Inputs'!$G$7="","",IF('Data Inputs'!$G$7="none","Needs Attention",IF('Data Inputs'!$G$7>=Thresholds!$D$7,"Satisfactory",IF('Data Inputs'!$G$7<Thresholds!$E$7,"At Risk","Needs Attention")))) | N9: =IF(M9<>"",M9,L9) | P9: =IF(N9="","Not scored",IF(AND(L9<>"",M9<>"",M9<>L9,O9=""),"Override: add evidence",IF(AND(E9<>"Data",N9<>"Satisfactory",O9=""),"Add evidence",""))) -> Not scored | Q9: Review open commitments, assign owners and dates, and send the client a status update before the next QBR. Don't let them discover the gaps in the meeting. | R9: =IF(N9="Satisfactory",Thresholds!$D$25,IF(N9="Needs Attention",Thresholds!$D$26,IF(N9="At Risk",Thresholds!$D$27,0))) -> 0 | S9: =IF(N9="At Risk",COUNTIF($N$5:N9,"At Risk"),IF(N9="Needs Attention",COUNTIF($N$5:$N$33,"At Risk")+COUNTIF($N$5:N9,"Needs Attention"),""))
A10: G6 | B10: Governance & Engagement | C10: How many people at the client do we have an active, direct relationship with? | D10: Single-threaded relationships fail when that one person leaves, goes quiet, or loses influence. | E10: Data | F10: N | G10: 2 | H10: ="At least "&TEXT(Thresholds!$D$8,"0")&" people across executive, operational, and staff levels" -> At least 3 people across executive, operational, and staff levels | I10: ="At least "&TEXT(Thresholds!$E$8,"0")&", fewer than "&TEXT(Thresholds!$D$8,"0") -> At least 2, fewer than 3 | J10: ="Fewer than "&TEXT(Thresholds!$E$8,"0")&" (single-threaded)" -> Fewer than 2 (single-threaded) | K10: ='Data Inputs'!$G$9 | L10: =IF('Data Inputs'!$G$9="","",IF('Data Inputs'!$G$9>=Thresholds!$D$8,"Satisfactory",IF('Data Inputs'!$G$9<Thresholds!$E$8,"At Risk","Needs Attention"))) | N10: =IF(M10<>"",M10,L10) | P10: =IF(N10="","Not scored",IF(AND(L10<>"",M10<>"",M10<>L10,O10=""),"Override: add evidence",IF(AND(E10<>"Data",N10<>"Satisfactory",O10=""),"Add evidence",""))) -> Not scored | Q10: Identify two additional stakeholders (one executive, one operational) and create a reason to engage each: a briefing, a project, or a check-in. | R10: =IF(N10="Satisfactory",Thresholds!$D$25,IF(N10="Needs Attention",Thresholds!$D$26,IF(N10="At Risk",Thresholds!$D$27,0))) -> 0 | S10: =IF(N10="At Risk",COUNTIF($N$5:N10,"At Risk"),IF(N10="Needs Attention",COUNTIF($N$5:$N$33,"At Risk")+COUNTIF($N$5:N10,"Needs Attention"),""))
A11: S1 | B11: Service Experience | C11: Is ticket volume per user consistent with the client's own baseline? | D11: Spikes point to an environment or service problem. Drops are the more dangerous signal: users have given up, are routing around us, or someone else is handling their issues. | E11: Data | F11: N | G11: 3 | H11: ="Between "&TEXT(Thresholds!$D$9,"0.00")&"x and "&TEXT(Thresholds!$D$10,"0.00")&"x of baseline" -> Between 0.75x and 1.25x of baseline | I11: ="Between "&TEXT(Thresholds!$E$9,"0.00")&"x-"&TEXT(Thresholds!$D$9,"0.00")&"x or "&TEXT(Thresholds!$D$10,"0.00")&"x-"&TEXT(Thresholds!$E$10,"0.00")&"x of baseline" -> Between 0.50x-0.75x or 1.25x-1.50x of baseline | J11: ="Below "&TEXT(Thresholds!$E$9,"0.00")&"x or above "&TEXT(Thresholds!$E$10,"0.00")&"x of baseline" -> Below 0.50x or above 1.50x of baseline | K11: ='Data Inputs'!$G$10 | L11: =IF('Data Inputs'!$G$10="","",IF(OR('Data Inputs'!$G$10<Thresholds!$E$9,'Data Inputs'!$G$10>Thresholds!$E$10),"At Risk",IF(OR('Data Inputs'!$G$10<Thresholds!$D$9,'Data Inputs'!$G$10>Thresholds!$D$10),"Needs Attention","Satisfactory"))) | N11: =IF(M11<>"",M11,L11) | P11: =IF(N11="","Not scored",IF(AND(L11<>"",M11<>"",M11<>L11,O11=""),"Override: add evidence",IF(AND(E11<>"Data",N11<>"Satisfactory",O11=""),"Add evidence",""))) -> Not scored | Q11: Find the cause before the QBR. For a drop, ask the client directly who is handling issues now. For a spike, review the top ticket categories and bring a remediation plan. | R11: =IF(N11="Satisfactory",Thresholds!$D$25,IF(N11="Needs Attention",Thresholds!$D$26,IF(N11="At Risk",Thresholds!$D$27,0))) -> 0 | S11: =IF(N11="At Risk",COUNTIF($N$5:N11,"At Risk"),IF(N11="Needs Attention",COUNTIF($N$5:$N$33,"At Risk")+COUNTIF($N$5:N11,"Needs Attention"),""))
A12: S2 | B12: Service Experience | C12: What share of requests bypass the service desk (direct texts or calls to techs, the owner, or the account manager)? | D12: Side-door requests signal that the client doesn't trust the front door, and they hide real workload from your metrics. | E12: Data | F12: N | G12: 2 | H12: ="No more than "&TEXT(Thresholds!$D$11,"0%")&" of tickets" -> No more than 5% of tickets | I12: ="Between "&TEXT(Thresholds!$D$11,"0%")&" and "&TEXT(Thresholds!$E$11,"0%")&"" -> Between 5% and 15% | J12: ="More than "&TEXT(Thresholds!$E$11,"0%")&"" -> More than 15% | K12: ='Data Inputs'!$G$13 | L12: =IF('Data Inputs'!$G$13="","",IF('Data Inputs'!$G$13<=Thresholds!$D$11,"Satisfactory",IF('Data Inputs'!$G$13>Thresholds!$E$11,"At Risk","Needs Attention"))) | N12: =IF(M12<>"",M12,L12) | P12: =IF(N12="","Not scored",IF(AND(L12<>"",M12<>"",M12<>L12,O12=""),"Override: add evidence",IF(AND(E12<>"Data",N12<>"Satisfactory",O12=""),"Add evidence",""))) -> Not scored | Q12: Find out why the front door is being avoided (response time, triage experience, a favored tech). Fix the cause, then reset expectations on how to get help. | R12: =IF(N12="Satisfactory",Thresholds!$D$25,IF(N12="Needs Attention",Thresholds!$D$26,IF(N12="At Risk",Thresholds!$D$27,0))) -> 0 | S12: =IF(N12="At Risk",COUNTIF($N$5:N12,"At Risk"),IF(N12="Needs Attention",COUNTIF($N$5:$N$33,"At Risk")+COUNTIF($N$5:N12,"Needs Attention"),""))
A13: S3 | B13: Service Experience | C13: What share of tickets are reopened or repeat a prior issue? | D13: Reopens are the client's experience of 'you didn't actually fix it.' | E13: Data | F13: N | G13: 1 | H13: ="No more than "&TEXT(Thresholds!$D$12,"0%")&" of tickets" -> No more than 5% of tickets | I13: ="Between "&TEXT(Thresholds!$D$12,"0%")&" and "&TEXT(Thresholds!$E$12,"0%")&"" -> Between 5% and 10% | J13: ="More than "&TEXT(Thresholds!$E$12,"0%")&"" -> More than 10% | K13: ='Data Inputs'!$G$14 | L13: =IF('Data Inputs'!$G$14="","",IF('Data Inputs'!$G$14<=Thresholds!$D$12,"Satisfactory",IF('Data Inputs'!$G$14>Thresholds!$E$12,"At Risk","Needs Attention"))) | N13: =IF(M13<>"",M13,L13) | P13: =IF(N13="","Not scored",IF(AND(L13<>"",M13<>"",M13<>L13,O13=""),"Override: add evidence",IF(AND(E13<>"Data",N13<>"Satisfactory",O13=""),"Add evidence",""))) -> Not scored | Q13: Review reopened tickets for root cause. Open a problem record for anything recurring and report the permanent fix at the QBR. | R13: =IF(N13="Satisfactory",Thresholds!$D$25,IF(N13="Needs Attention",Thresholds!$D$26,IF(N13="At Risk",Thresholds!$D$27,0))) -> 0 | S13: =IF(N13="At Risk",COUNTIF($N$5:N13,"At Risk"),IF(N13="Needs Attention",COUNTIF($N$5:$N$33,"At Risk")+COUNTIF($N$5:N13,"Needs Attention"),""))
A14: S4 | B14: Service Experience | C14: Are we meeting SLA on this client's tickets? | D14: SLA attainment is the floor of the relationship. Clients rarely praise it but always notice when it slips. | E14: Data | F14: N | G14: 2 | H14: ="At least "&TEXT(Thresholds!$D$13,"0%")&"" -> At least 95% | I14: ="Between "&TEXT(Thresholds!$E$13,"0%")&" and "&TEXT(Thresholds!$D$13,"0%")&"" -> Between 85% and 95% | J14: ="Below "&TEXT(Thresholds!$E$13,"0%")&"" -> Below 85% | K14: ='Data Inputs'!$G$15 | L14: =IF('Data Inputs'!$G$15="","",IF('Data Inputs'!$G$15>=Thresholds!$D$13,"Satisfactory",IF('Data Inputs'!$G$15<Thresholds!$E$13,"At Risk","Needs Attention"))) | N14: =IF(M14<>"",M14,L14) | P14: =IF(N14="","Not scored",IF(AND(L14<>"",M14<>"",M14<>L14,O14=""),"Override: add evidence",IF(AND(E14<>"Data",N14<>"Satisfactory",O14=""),"Add evidence",""))) -> Not scored | Q14: Review SLA misses by queue and time of day, correct the dispatch or staffing issue, and disclose performance to the client before they raise it. | R14: =IF(N14="Satisfactory",Thresholds!$D$25,IF(N14="Needs Attention",Thresholds!$D$26,IF(N14="At Risk",Thresholds!$D$27,0))) -> 0 | S14: =IF(N14="At Risk",COUNTIF($N$5:N14,"At Risk"),IF(N14="Needs Attention",COUNTIF($N$5:$N$33,"At Risk")+COUNTIF($N$5:N14,"Needs Attention"),""))
A15: S5 | B15: Service Experience | C15: How many times has the client's assigned primary tech or TAM changed in the last 12 months? | D15: Clients buy relationships with people. Rotating the people resets trust every time. | E15: Data | F15: N | G15: 2 | H15: =IF(Thresholds!$D$14=0,"None","No more than "&Thresholds!$D$14&" change(s)") -> None | I15: =IF(Thresholds!$E$14-Thresholds!$D$14=1,Thresholds!$E$14&" change(s)","Between "&(Thresholds!$D$14+1)&" and "&Thresholds!$E$14&" change(s)") -> 1 change(s) | J15: =(Thresholds!$E$14+1)&" or more change(s)" -> 2 or more change(s) | K15: ='Data Inputs'!$G$16 | L15: =IF('Data Inputs'!$G$16="","",IF('Data Inputs'!$G$16<=Thresholds!$D$14,"Satisfactory",IF('Data Inputs'!$G$16>Thresholds!$E$14,"At Risk","Needs Attention"))) | N15: =IF(M15<>"",M15,L15) | P15: =IF(N15="","Not scored",IF(AND(L15<>"",M15<>"",M15<>L15,O15=""),"Override: add evidence",IF(AND(E15<>"Data",N15<>"Satisfactory",O15=""),"Add evidence",""))) -> Not scored | Q15: Stabilize the assignment. If a change is unavoidable, make it a warm hand-off with an introduction meeting, not an email. | R15: =IF(N15="Satisfactory",Thresholds!$D$25,IF(N15="Needs Attention",Thresholds!$D$26,IF(N15="At Risk",Thresholds!$D$27,0))) -> 0 | S15: =IF(N15="At Risk",COUNTIF($N$5:N15,"At Risk"),IF(N15="Needs Attention",COUNTIF($N$5:$N$33,"At Risk")+COUNTIF($N$5:N15,"Needs Attention"),""))
A16: F1 | B16: Feedback Loop | C16: What share of CSAT surveys does the client respond to? | D16: Response rate matters more than score. A client that stops answering has stopped telling you how they feel, not stopped feeling it. | E16: Data | F16: N | G16: 3 | H16: ="At least "&TEXT(Thresholds!$D$15,"0%")&" response rate" -> At least 20% response rate | I16: ="Between "&TEXT(Thresholds!$E$15,"0%")&" and "&TEXT(Thresholds!$D$15,"0%")&"" -> Between 10% and 20% | J16: ="Below "&TEXT(Thresholds!$E$15,"0%")&"" -> Below 10% | K16: ='Data Inputs'!$G$17 | L16: =IF('Data Inputs'!$G$17="","",IF('Data Inputs'!$G$17>=Thresholds!$D$15,"Satisfactory",IF('Data Inputs'!$G$17<Thresholds!$E$15,"At Risk","Needs Attention"))) | N16: =IF(M16<>"",M16,L16) | P16: =IF(N16="","Not scored",IF(AND(L16<>"",M16<>"",M16<>L16,O16=""),"Override: add evidence",IF(AND(E16<>"Data",N16<>"Satisfactory",O16=""),"Add evidence",""))) -> Not scored | Q16: Ask the primary contact how they prefer to give feedback. Consider a short quarterly relationship check-in in place of relying on ticket surveys. | R16: =IF(N16="Satisfactory",Thresholds!$D$25,IF(N16="Needs Attention",Thresholds!$D$26,IF(N16="At Risk",Thresholds!$D$27,0))) -> 0 | S16: =IF(N16="At Risk",COUNTIF($N$5:N16,"At Risk"),IF(N16="Needs Attention",COUNTIF($N$5:$N$33,"At Risk")+COUNTIF($N$5:N16,"Needs Attention"),""))
A17: F2 | B17: Feedback Loop | C17: What share of CSAT responses are positive? | D17: Score still matters; it just isn't the whole story when response volume is low. | E17: Data | F17: N | G17: 2 | H17: ="At least "&TEXT(Thresholds!$D$16,"0%")&" positive" -> At least 95% positive | I17: ="Between "&TEXT(Thresholds!$E$16,"0%")&" and "&TEXT(Thresholds!$D$16,"0%")&"" -> Between 90% and 95% | J17: ="Below "&TEXT(Thresholds!$E$16,"0%")&"" -> Below 90% | K17: ='Data Inputs'!$G$19 | L17: =IF('Data Inputs'!$G$19="","",IF('Data Inputs'!$G$19>=Thresholds!$D$16,"Satisfactory",IF('Data Inputs'!$G$19<Thresholds!$E$16,"At Risk","Needs Attention"))) | N17: =IF(M17<>"",M17,L17) | P17: =IF(N17="","Not scored",IF(AND(L17<>"",M17<>"",M17<>L17,O17=""),"Override: add evidence",IF(AND(E17<>"Data",N17<>"Satisfactory",O17=""),"Add evidence",""))) -> Not scored | Q17: Read every non-positive response from the period, identify the pattern, and address it with the client by name. | R17: =IF(N17="Satisfactory",Thresholds!$D$25,IF(N17="Needs Attention",Thresholds!$D$26,IF(N17="At Risk",Thresholds!$D$27,0))) -> 0 | S17: =IF(N17="At Risk",COUNTIF($N$5:N17,"At Risk"),IF(N17="Needs Attention",COUNTIF($N$5:$N$33,"At Risk")+COUNTIF($N$5:N17,"Needs Attention"),""))
A18: F3 | B18: Feedback Loop | C18: Was every negative CSAT response followed up by a person within 2 business days? | D18: A negative survey with no response tells the client the survey is theater. | E18: Data | F18: N | G18: 2 | H18: =IF(Thresholds!$D$17>=1,"All","At least "&TEXT(Thresholds!$D$17,"0%"))&" followed up, or no negative responses" -> All followed up, or no negative responses | I18: ="Between "&TEXT(Thresholds!$E$17,"0%")&" and "&TEXT(Thresholds!$D$17,"0%")&"" -> Between 75% and 100% | J18: ="Below "&TEXT(Thresholds!$E$17,"0%")&"" -> Below 75% | K18: ='Data Inputs'!$G$20 | L18: =IF('Data Inputs'!$G$20="","",IF('Data Inputs'!$G$20="none","Satisfactory",IF('Data Inputs'!$G$20>=Thresholds!$D$17,"Satisfactory",IF('Data Inputs'!$G$20<Thresholds!$E$17,"At Risk","Needs Attention")))) | N18: =IF(M18<>"",M18,L18) | P18: =IF(N18="","Not scored",IF(AND(L18<>"",M18<>"",M18<>L18,O18=""),"Override: add evidence",IF(AND(E18<>"Data",N18<>"Satisfactory",O18=""),"Add evidence",""))) -> Not scored | Q18: Close the open loops now with a call from a manager, not an email. Route negative responses to a named person the same day going forward. | R18: =IF(N18="Satisfactory",Thresholds!$D$25,IF(N18="Needs Attention",Thresholds!$D$26,IF(N18="At Risk",Thresholds!$D$27,0))) -> 0 | S18: =IF(N18="At Risk",COUNTIF($N$5:N18,"At Risk"),IF(N18="Needs Attention",COUNTIF($N$5:$N$33,"At Risk")+COUNTIF($N$5:N18,"Needs Attention"),""))
A19: F4 | B19: Feedback Loop | C19: When the client is unhappy, do they escalate through the defined path? | D19: Healthy clients complain early and through the right channel. Dissatisfaction that surfaces late, sideways, or at renewal means the path isn't trusted or isn't known. | E19: Judgment | F19: Y | G19: 3 | H19: Concerns are raised promptly to the account manager, vCIO, or defined escalation contact. | I19: Concerns surface late or informally: in passing, only at QBRs, or through a technician. | J19: Concerns surface through an owner or executive bypass, third parties, formal complaints, or at renewal, or we learned of dissatisfaction after the fact. | K19: n/a | N19: =IF(M19<>"",M19,L19) -> 0 | P19: =IF(N19="","Not scored",IF(AND(L19<>"",M19<>"",M19<>L19,O19=""),"Override: add evidence",IF(AND(E19<>"Data",N19<>"Satisfactory",O19=""),"Add evidence",""))) -> Not scored | Q19: Re-communicate the escalation path in writing with a named person, and ask the client directly whether anything is currently unresolved. | R19: =IF(N19="Satisfactory",Thresholds!$D$25,IF(N19="Needs Attention",Thresholds!$D$26,IF(N19="At Risk",Thresholds!$D$27,0))) -> 0 | S19: =IF(N19="At Risk",COUNTIF($N$5:N19,"At Risk"),IF(N19="Needs Attention",COUNTIF($N$5:$N$33,"At Risk")+COUNTIF($N$5:N19,"Needs Attention"),""))
A20: F5 | B20: Feedback Loop | C20: What is the client's overall sentiment toward us, based on recent direct conversation? | D20: The assessor's read of the room. Weighted low on purpose; the data items carry more of the score. | E20: Judgment | F20: N | G20: 1 | H20: Positive: the client expresses confidence in us and refers to us as a partner. | I20: Neutral or transactional: no complaints, no enthusiasm. | J20: Negative: frustration, skepticism, or a focus on price in recent conversations. | K20: n/a | N20: =IF(M20<>"",M20,L20) -> 0 | P20: =IF(N20="","Not scored",IF(AND(L20<>"",M20<>"",M20<>L20,O20=""),"Override: add evidence",IF(AND(E20<>"Data",N20<>"Satisfactory",O20=""),"Add evidence",""))) -> Not scored | Q20: Have a direct conversation and ask: 'If you were to replace us, what would the reason be?' Act on the answer. | R20: =IF(N20="Satisfactory",Thresholds!$D$25,IF(N20="Needs Attention",Thresholds!$D$26,IF(N20="At Risk",Thresholds!$D$27,0))) -> 0 | S20: =IF(N20="At Risk",COUNTIF($N$5:N20,"At Risk"),IF(N20="Needs Attention",COUNTIF($N$5:$N$33,"At Risk")+COUNTIF($N$5:N20,"Needs Attention"),""))
A21: C1 | B21: Commercial Health | C21: Is the client paying on time, and is payment timing stable? | D21: Slowing payment often precedes a cancellation conversation, or reflects financial strain at the client. | E21: Data | F21: N | G21: 3 | H21: =IF(Thresholds!$D$18=0,"Paid within terms","No more than "&TEXT(Thresholds!$D$18,"0")&" days over terms")&", and not slowing by more than "&TEXT(Thresholds!$D$19,"0")&" days" -> Paid within terms, and not slowing by more than 5 days | I21: ="Up to "&TEXT(Thresholds!$E$18,"0")&" days over terms, or slowing by up to "&TEXT(Thresholds!$E$19,"0")&" days" -> Up to 15 days over terms, or slowing by up to 15 days | J21: ="More than "&TEXT(Thresholds!$E$18,"0")&" days over terms, or slowing by more than "&TEXT(Thresholds!$E$19,"0")&" days vs. prior 90 days" -> More than 15 days over terms, or slowing by more than 15 days vs. prior 90 days | K21: ='Data Inputs'!$G$22 | L21: =IF('Data Inputs'!$G$22="","",IF(OR('Data Inputs'!$G$22>Thresholds!$E$18,IF('Data Inputs'!$D$23="",0,'Data Inputs'!$D$22-'Data Inputs'!$D$23)>Thresholds!$E$19),"At Risk",IF(OR('Data Inputs'!$G$22>Thresholds!$D$18,IF('Data Inputs'!$D$23="",0,'Data Inputs'!$D$22-'Data Inputs'!$D$23)>Thresholds!$D$19),"Needs Attention","Satisfactory"))) | N21: =IF(M21<>"",M21,L21) | P21: =IF(N21="","Not scored",IF(AND(L21<>"",M21<>"",M21<>L21,O21=""),"Override: add evidence",IF(AND(E21<>"Data",N21<>"Satisfactory",O21=""),"Add evidence",""))) -> Not scored | Q21: Have finance and the account manager compare notes. If the cause is dissatisfaction, address it before the next invoice cycle; if it's cash flow, discuss it openly. | R21: =IF(N21="Satisfactory",Thresholds!$D$25,IF(N21="Needs Attention",Thresholds!$D$26,IF(N21="At Risk",Thresholds!$D$27,0))) -> 0 | S21: =IF(N21="At Risk",COUNTIF($N$5:N21,"At Risk"),IF(N21="Needs Attention",COUNTIF($N$5:$N$33,"At Risk")+COUNTIF($N$5:N21,"Needs Attention"),""))
A22: C2 | B22: Commercial Health | C22: What share of proposed initiatives or projects did the client approve in the last 12 months? | D22: Approval rate measures trust in our recommendations. Zero proposals presented is a finding about us, not the client. | E22: Data | F22: N | G22: 2 | H22: ="At least "&TEXT(Thresholds!$D$20,"0%")&" approved" -> At least 60% approved | I22: ="Between "&TEXT(Thresholds!$E$20,"0%")&" and "&TEXT(Thresholds!$D$20,"0%")&", or no proposals presented" -> Between 30% and 60%, or no proposals presented | J22: ="Below "&TEXT(Thresholds!$E$20,"0%")&"" -> Below 30% | K22: ='Data Inputs'!$G$24 | L22: =IF('Data Inputs'!$G$24="","",IF('Data Inputs'!$G$24="none","Needs Attention",IF('Data Inputs'!$G$24>=Thresholds!$D$20,"Satisfactory",IF('Data Inputs'!$G$24<Thresholds!$E$20,"At Risk","Needs Attention")))) | N22: =IF(M22<>"",M22,L22) | P22: =IF(N22="","Not scored",IF(AND(L22<>"",M22<>"",M22<>L22,O22=""),"Override: add evidence",IF(AND(E22<>"Data",N22<>"Satisfactory",O22=""),"Add evidence",""))) -> Not scored | Q22: Review declined proposals for the reason (budget, timing, relevance) and re-align the roadmap to the client's stated business priorities. | R22: =IF(N22="Satisfactory",Thresholds!$D$25,IF(N22="Needs Attention",Thresholds!$D$26,IF(N22="At Risk",Thresholds!$D$27,0))) -> 0 | S22: =IF(N22="At Risk",COUNTIF($N$5:N22,"At Risk"),IF(N22="Needs Attention",COUNTIF($N$5:$N$33,"At Risk")+COUNTIF($N$5:N22,"Needs Attention"),""))
A23: C3 | B23: Commercial Health | C23: How many proposals have been open more than 60 days without a decision? | D23: Stalled quotes signal indecision or a quiet 'no', and they clutter the roadmap. | E23: Data | F23: N | G23: 1 | H23: =IF(Thresholds!$D$21=0,"None","No more than "&Thresholds!$D$21&"") -> None | I23: =IF(Thresholds!$E$21-Thresholds!$D$21=1,Thresholds!$E$21&"","Between "&(Thresholds!$D$21+1)&" and "&Thresholds!$E$21&"") -> Between 1 and 2 | J23: =(Thresholds!$E$21+1)&" or more" -> 3 or more | K23: ='Data Inputs'!$G$26 | L23: =IF('Data Inputs'!$G$26="","",IF('Data Inputs'!$G$26<=Thresholds!$D$21,"Satisfactory",IF('Data Inputs'!$G$26>Thresholds!$E$21,"At Risk","Needs Attention"))) | N23: =IF(M23<>"",M23,L23) | P23: =IF(N23="","Not scored",IF(AND(L23<>"",M23<>"",M23<>L23,O23=""),"Override: add evidence",IF(AND(E23<>"Data",N23<>"Satisfactory",O23=""),"Add evidence",""))) -> Not scored | Q23: Get a decision on each one: approve, defer to a specific date, or withdraw. | R23: =IF(N23="Satisfactory",Thresholds!$D$25,IF(N23="Needs Attention",Thresholds!$D$26,IF(N23="At Risk",Thresholds!$D$27,0))) -> 0 | S23: =IF(N23="At Risk",COUNTIF($N$5:N23,"At Risk"),IF(N23="Needs Attention",COUNTIF($N$5:$N$33,"At Risk")+COUNTIF($N$5:N23,"Needs Attention"),""))
A24: C4 | B24: Commercial Health | C24: Does the agreement reflect what the client actually consumes, without billing or scope friction? | D24: Scope and billing friction turn every invoice into a negotiation. | E24: Judgment | F24: N | G24: 2 | H24: Billing matches current users and devices, there are no disputes, and scope boundaries are understood. | I24: True-ups lag, or there is occasional pushback on out-of-scope charges. | J24: There is an active billing dispute, or recurring conflict over what is in scope. | K24: n/a | N24: =IF(M24<>"",M24,L24) -> 0 | P24: =IF(N24="","Not scored",IF(AND(L24<>"",M24<>"",M24<>L24,O24=""),"Override: add evidence",IF(AND(E24<>"Data",N24<>"Satisfactory",O24=""),"Add evidence",""))) -> Not scored | Q24: Run an agreement reconciliation, correct billing, and walk the client through what is and isn't covered, in writing. | R24: =IF(N24="Satisfactory",Thresholds!$D$25,IF(N24="Needs Attention",Thresholds!$D$26,IF(N24="At Risk",Thresholds!$D$27,0))) -> 0 | S24: =IF(N24="At Risk",COUNTIF($N$5:N24,"At Risk"),IF(N24="Needs Attention",COUNTIF($N$5:$N$33,"At Risk")+COUNTIF($N$5:N24,"Needs Attention"),""))
A25: A1 | B25: Strategic Alignment | C25: Does the client involve us before making technology decisions or purchases? | D25: Technology bought without us is shadow IT today and a support problem tomorrow. It also shows how the client sees our role. | E25: Judgment | F25: N | G25: 3 | H25: The client consults us before purchases and before engaging new technology vendors. | I25: The client informs us after the fact, inconsistently. | J25: The client regularly makes technology decisions or engages other IT providers without us. | K25: n/a | N25: =IF(M25<>"",M25,L25) -> 0 | P25: =IF(N25="","Not scored",IF(AND(L25<>"",M25<>"",M25<>L25,O25=""),"Override: add evidence",IF(AND(E25<>"Data",N25<>"Satisfactory",O25=""),"Add evidence",""))) -> Not scored | Q25: Ask what was purchased and why we weren't involved. Establish a simple 'check with us first' step tied to the roadmap. | R25: =IF(N25="Satisfactory",Thresholds!$D$25,IF(N25="Needs Attention",Thresholds!$D$26,IF(N25="At Risk",Thresholds!$D$27,0))) -> 0 | S25: =IF(N25="At Risk",COUNTIF($N$5:N25,"At Risk"),IF(N25="Needs Attention",COUNTIF($N$5:$N$33,"At Risk")+COUNTIF($N$5:N25,"Needs Attention"),""))
A26: A2 | B26: Strategic Alignment | C26: Do we know the client's business plans and priorities for the next 12 months? | D26: A roadmap built without the business plan is a list of technology we'd like to sell. | E26: Judgment | F26: N | G26: 2 | H26: We know their growth plans, major initiatives, and constraints, and the roadmap reflects them. | I26: Partial understanding; the roadmap is mostly technology-driven. | J26: We don't know their business plans. | K26: n/a | N26: =IF(M26<>"",M26,L26) -> 0 | P26: =IF(N26="","Not scored",IF(AND(L26<>"",M26<>"",M26<>L26,O26=""),"Override: add evidence",IF(AND(E26<>"Data",N26<>"Satisfactory",O26=""),"Add evidence",""))) -> Not scored | Q26: Use the next QBR to interview the decision-maker about business goals before presenting any technology. | R26: =IF(N26="Satisfactory",Thresholds!$D$25,IF(N26="Needs Attention",Thresholds!$D$26,IF(N26="At Risk",Thresholds!$D$27,0))) -> 0 | S26: =IF(N26="At Risk",COUNTIF($N$5:N26,"At Risk"),IF(N26="Needs Attention",COUNTIF($N$5:$N$33,"At Risk")+COUNTIF($N$5:N26,"Needs Attention"),""))
A27: A3 | B27: Strategic Alignment | C27: Is there a current, client-reviewed 12-month technology roadmap and budget? | D27: Without an agreed roadmap, every recommendation is a surprise and every invoice is unplanned. | E27: Judgment | F27: N | G27: 2 | H27: A roadmap and budget were reviewed with the client in the last 6 months. | I27: A roadmap exists but has not been reviewed with the client in 6+ months. | J27: No roadmap or budget exists for this client. | K27: n/a | N27: =IF(M27<>"",M27,L27) -> 0 | P27: =IF(N27="","Not scored",IF(AND(L27<>"",M27<>"",M27<>L27,O27=""),"Override: add evidence",IF(AND(E27<>"Data",N27<>"Satisfactory",O27=""),"Add evidence",""))) -> Not scored | Q27: Build or refresh the roadmap from the latest assessment results and review it with the decision-maker. | R27: =IF(N27="Satisfactory",Thresholds!$D$25,IF(N27="Needs Attention",Thresholds!$D$26,IF(N27="At Risk",Thresholds!$D$27,0))) -> 0 | S27: =IF(N27="At Risk",COUNTIF($N$5:N27,"At Risk"),IF(N27="Needs Attention",COUNTIF($N$5:$N$33,"At Risk")+COUNTIF($N$5:N27,"Needs Attention"),""))
A28: A4 | B28: Strategic Alignment | C28: How does the client view our role? | D28: Strategic advisors get renewed on value. Commodity providers get renewed on price, until someone is cheaper. | E28: Judgment | F28: N | G28: 2 | H28: Strategic advisor: we are invited into planning conversations. | I28: Trusted vendor: reliable, but engaged only for IT matters. | J28: Commodity provider: the relationship is driven by price and contract terms. | K28: n/a | N28: =IF(M28<>"",M28,L28) -> 0 | P28: =IF(N28="","Not scored",IF(AND(L28<>"",M28<>"",M28<>L28,O28=""),"Override: add evidence",IF(AND(E28<>"Data",N28<>"Satisfactory",O28=""),"Add evidence",""))) -> Not scored | Q28: Bring one business-relevant insight to every interaction for the next quarter, and track whether the client starts pulling us into planning. | R28: =IF(N28="Satisfactory",Thresholds!$D$25,IF(N28="Needs Attention",Thresholds!$D$26,IF(N28="At Risk",Thresholds!$D$27,0))) -> 0 | S28: =IF(N28="At Risk",COUNTIF($N$5:N28,"At Risk"),IF(N28="Needs Attention",COUNTIF($N$5:$N$33,"At Risk")+COUNTIF($N$5:N28,"Needs Attention"),""))
A29: R1 | B29: Risk Triggers | C29: Has the client had an ownership change, merger, acquisition, or senior leadership change in the last 12 months, or is one announced? | D29: New owners and new leaders review every vendor. | E29: Trigger | F29: Y | G29: 1 | H29: No. | I29: Unknown: we haven't asked. | J29: Yes. | K29: n/a | N29: =IF(M29<>"",M29,L29) -> 0 | P29: =IF(N29="","Not scored",IF(AND(L29<>"",M29<>"",M29<>L29,O29=""),"Override: add evidence",IF(AND(E29<>"Data",N29<>"Satisfactory",O29=""),"Add evidence",""))) -> Not scored | Q29: Meet the new leadership, confirm who holds decision rights, and re-present the value of the agreement. | R29: =IF(N29="Satisfactory",Thresholds!$D$25,IF(N29="Needs Attention",Thresholds!$D$26,IF(N29="At Risk",Thresholds!$D$27,0))) -> 0 | S29: =IF(N29="At Risk",COUNTIF($N$5:N29,"At Risk"),IF(N29="Needs Attention",COUNTIF($N$5:$N$33,"At Risk")+COUNTIF($N$5:N29,"Needs Attention"),""))
A30: R2 | B30: Risk Triggers | C30: Has the client hired, or announced plans to hire, internal IT staff? | D30: An internal hire changes the relationship whether we plan for it or not. | E30: Trigger | F30: Y | G30: 1 | H30: No. | I30: Unknown: we haven't asked. | J30: Yes. | K30: n/a | N30: =IF(M30<>"",M30,L30) -> 0 | P30: =IF(N30="","Not scored",IF(AND(L30<>"",M30<>"",M30<>L30,O30=""),"Override: add evidence",IF(AND(E30<>"Data",N30<>"Satisfactory",O30=""),"Add evidence",""))) -> Not scored | Q30: Position for co-managed. Meet the new hire early, define responsibilities, and make them successful rather than competing with them. | R30: =IF(N30="Satisfactory",Thresholds!$D$25,IF(N30="Needs Attention",Thresholds!$D$26,IF(N30="At Risk",Thresholds!$D$27,0))) -> 0 | S30: =IF(N30="At Risk",COUNTIF($N$5:N30,"At Risk"),IF(N30="Needs Attention",COUNTIF($N$5:$N$33,"At Risk")+COUNTIF($N$5:N30,"Needs Attention"),""))
A31: R3 | B31: Risk Triggers | C31: Is the client known to be talking with another provider or issuing an RFP? | D31: By the time it's visible, the evaluation is usually well underway. | E31: Trigger | F31: Y | G31: 1 | H31: No. | I31: Unknown: we haven't asked. | J31: Yes. | K31: n/a | N31: =IF(M31<>"",M31,L31) -> 0 | P31: =IF(N31="","Not scored",IF(AND(L31<>"",M31<>"",M31<>L31,O31=""),"Override: add evidence",IF(AND(E31<>"Data",N31<>"Satisfactory",O31=""),"Add evidence",""))) -> Not scored | Q31: Hold an executive-level conversation immediately. Ask directly what prompted it and what would need to change. | R31: =IF(N31="Satisfactory",Thresholds!$D$25,IF(N31="Needs Attention",Thresholds!$D$26,IF(N31="At Risk",Thresholds!$D$27,0))) -> 0 | S31: =IF(N31="At Risk",COUNTIF($N$5:N31,"At Risk"),IF(N31="Needs Attention",COUNTIF($N$5:$N$33,"At Risk")+COUNTIF($N$5:N31,"Needs Attention"),""))
A32: R4 | B32: Risk Triggers | C32: Has the client announced budget cuts, layoffs, or shown signs of financial distress? | D32: Budget pressure turns a managed services agreement into a line item to cut. | E32: Trigger | F32: Y | G32: 1 | H32: No. | I32: Unknown: we haven't asked. | J32: Yes. | K32: n/a | N32: =IF(M32<>"",M32,L32) -> 0 | P32: =IF(N32="","Not scored",IF(AND(L32<>"",M32<>"",M32<>L32,O32=""),"Override: add evidence",IF(AND(E32<>"Data",N32<>"Satisfactory",O32=""),"Add evidence",""))) -> Not scored | Q32: Proactively offer options to right-size the agreement and protect core services before the client decides on its own. | R32: =IF(N32="Satisfactory",Thresholds!$D$25,IF(N32="Needs Attention",Thresholds!$D$26,IF(N32="At Risk",Thresholds!$D$27,0))) -> 0 | S32: =IF(N32="At Risk",COUNTIF($N$5:N32,"At Risk"),IF(N32="Needs Attention",COUNTIF($N$5:$N$33,"At Risk")+COUNTIF($N$5:N32,"Needs Attention"),""))
A33: R5 | B33: Risk Triggers | C33: Has there been a major outage or security incident in the last 12 months without a completed post-incident review with the client? | D33: An incident without a review leaves the client to write their own version of what happened. | E33: Trigger | F33: Y | G33: 1 | H33: No, or the review is complete. | I33: Unknown, or the review is scheduled but not held. | J33: Yes. | K33: n/a | N33: =IF(M33<>"",M33,L33) -> 0 | P33: =IF(N33="","Not scored",IF(AND(L33<>"",M33<>"",M33<>L33,O33=""),"Override: add evidence",IF(AND(E33<>"Data",N33<>"Satisfactory",O33=""),"Add evidence",""))) -> Not scored | Q33: Schedule the post-incident review now: what happened, what we changed, and what the client should expect going forward. | R33: =IF(N33="Satisfactory",Thresholds!$D$25,IF(N33="Needs Attention",Thresholds!$D$26,IF(N33="At Risk",Thresholds!$D$27,0))) -> 0 | S33: =IF(N33="At Risk",COUNTIF($N$5:N33,"At Risk"),IF(N33="Needs Attention",COUNTIF($N$5:$N$33,"At Risk")+COUNTIF($N$5:N33,"Needs Attention"),""))

Sheet Summary
A1: Relationship Health Summary | G1: [ Your logo ]
A2: INTERNAL USE ONLY. Do not share with the client.
A5: Client | B5: =IF('Client Info'!$B$6="","",'Client Info'!$B$6) | E5: Overall score | F5: =IF(SUMPRODUCT(Assessment!$G$5:$G$33,--(Assessment!$N$5:$N$33<>""))=0,"",ROUND(SUMPRODUCT(Assessment!$G$5:$G$33,Assessment!$R$5:$R$33)/SUMPRODUCT(Assessment!$G$5:$G$33,--(Assessment!$N$5:$N$33<>"")),0))
A6: Assessing MSP | B6: =IF('Client Info'!$B$5="","",'Client Info'!$B$5) | E6: Overall rating | F6: =IF(F5="","Not scored",IF(AND(Thresholds!$D$30="Yes",F8>0),"At Risk",IF(F5>=Thresholds!$D$28,"Healthy",IF(F5>=Thresholds!$D$29,"Watch","At Risk")))) -> Not scored
A7: Assessment date | B7: =IF('Client Info'!$B$7="","",'Client Info'!$B$7) | E7: Items scored | F7: =SUMPRODUCT(--(Assessment!$N$5:$N$33<>""))&" of 29" -> 0 of 29
A8: Assessor | B8: =IF('Client Info'!$B$8="","",'Client Info'!$B$8) | E8: Critical items At Risk | F8: =SUMPRODUCT((Assessment!$F$5:$F$33="Y")*(Assessment!$N$5:$N$33="At Risk")) -> 0
A9: Renewal date | B9: =IF('Client Info'!$B$14="","",'Client Info'!$B$14) | E9: Previous score | F9: =IF('Client Info'!$B$21="","",'Client Info'!$B$21)
A10: Days to renewal | B10: =IF('Client Info'!$B$15="","",'Client Info'!$B$15) | E10: Change | F10: =IF(OR(F5="",F9=""),"",F5-F9)
A12: Alerts
A13: =IF(AND('Client Info'!$B$15<>"",'Client Info'!$B$15<=Thresholds!$D$31,F6<>"Healthy",F6<>"Not scored"),"Renewal in "&'Client Info'!$B$15&" days with a rating of "&F6&". Start renewal recovery now.","No renewal alert.") -> No renewal alert.
A14: =IF(F8>0,F8&" critical item(s) rated At Risk. Overall rating forced to At Risk regardless of score.","No critical items At Risk.") -> No critical items At Risk.
A15: =IF(COUNTIF(Assessment!$P$5:$P$33,"Add evidence")+COUNTIF(Assessment!$P$5:$P$33,"Override: add evidence")>0,COUNTIF(Assessment!$P$5:$P$33,"Add evidence")+COUNTIF(Assessment!$P$5:$P$33,"Override: add evidence")&" scored item(s) are missing evidence. Complete before the review.","Evidence complete for all scored items.") -> Evidence complete for all scored items.
A16: =IF(COUNTIF(Assessment!$P$5:$P$33,"Not scored")>0,COUNTIF(Assessment!$P$5:$P$33,"Not scored")&" item(s) not yet scored. The score reflects scored items only.","All items scored.") -> 29 item(s) not yet scored. The score reflects scored items only.
A18: Score by dimension
A19: Dimension | B19: Items | C19: Scored | D19: Score | E19: Satisfactory | F19: Needs Attention | G19: At Risk | H19: Weakest signal
A20: Governance & Engagement | B20: =COUNTIF(Assessment!$B$5:$B$33,A20) -> 6 | C20: =SUMPRODUCT((Assessment!$B$5:$B$33=A20)*(Assessment!$N$5:$N$33<>"")) -> 0 | D20: =IF(C20=0,"",ROUND(SUMPRODUCT((Assessment!$B$5:$B$33=A20)*Assessment!$G$5:$G$33*Assessment!$R$5:$R$33)/SUMPRODUCT((Assessment!$B$5:$B$33=A20)*Assessment!$G$5:$G$33*(Assessment!$N$5:$N$33<>"")),0)) | E20: =COUNTIFS(Assessment!$B$5:$B$33,A20,Assessment!$N$5:$N$33,"Satisfactory") -> 0 | F20: =COUNTIFS(Assessment!$B$5:$B$33,A20,Assessment!$N$5:$N$33,"Needs Attention") -> 0 | G20: =COUNTIFS(Assessment!$B$5:$B$33,A20,Assessment!$N$5:$N$33,"At Risk") -> 0 | H20: =IF(G20>0,"At Risk items present",IF(F20>0,"Needs Attention items present",IF(C20=0,"Not scored",""))) -> Not scored
A21: Service Experience | B21: =COUNTIF(Assessment!$B$5:$B$33,A21) -> 5 | C21: =SUMPRODUCT((Assessment!$B$5:$B$33=A21)*(Assessment!$N$5:$N$33<>"")) -> 0 | D21: =IF(C21=0,"",ROUND(SUMPRODUCT((Assessment!$B$5:$B$33=A21)*Assessment!$G$5:$G$33*Assessment!$R$5:$R$33)/SUMPRODUCT((Assessment!$B$5:$B$33=A21)*Assessment!$G$5:$G$33*(Assessment!$N$5:$N$33<>"")),0)) | E21: =COUNTIFS(Assessment!$B$5:$B$33,A21,Assessment!$N$5:$N$33,"Satisfactory") -> 0 | F21: =COUNTIFS(Assessment!$B$5:$B$33,A21,Assessment!$N$5:$N$33,"Needs Attention") -> 0 | G21: =COUNTIFS(Assessment!$B$5:$B$33,A21,Assessment!$N$5:$N$33,"At Risk") -> 0 | H21: =IF(G21>0,"At Risk items present",IF(F21>0,"Needs Attention items present",IF(C21=0,"Not scored",""))) -> Not scored
A22: Feedback Loop | B22: =COUNTIF(Assessment!$B$5:$B$33,A22) -> 5 | C22: =SUMPRODUCT((Assessment!$B$5:$B$33=A22)*(Assessment!$N$5:$N$33<>"")) -> 0 | D22: =IF(C22=0,"",ROUND(SUMPRODUCT((Assessment!$B$5:$B$33=A22)*Assessment!$G$5:$G$33*Assessment!$R$5:$R$33)/SUMPRODUCT((Assessment!$B$5:$B$33=A22)*Assessment!$G$5:$G$33*(Assessment!$N$5:$N$33<>"")),0)) | E22: =COUNTIFS(Assessment!$B$5:$B$33,A22,Assessment!$N$5:$N$33,"Satisfactory") -> 0 | F22: =COUNTIFS(Assessment!$B$5:$B$33,A22,Assessment!$N$5:$N$33,"Needs Attention") -> 0 | G22: =COUNTIFS(Assessment!$B$5:$B$33,A22,Assessment!$N$5:$N$33,"At Risk") -> 0 | H22: =IF(G22>0,"At Risk items present",IF(F22>0,"Needs Attention items present",IF(C22=0,"Not scored",""))) -> Not scored
A23: Commercial Health | B23: =COUNTIF(Assessment!$B$5:$B$33,A23) -> 4 | C23: =SUMPRODUCT((Assessment!$B$5:$B$33=A23)*(Assessment!$N$5:$N$33<>"")) -> 0 | D23: =IF(C23=0,"",ROUND(SUMPRODUCT((Assessment!$B$5:$B$33=A23)*Assessment!$G$5:$G$33*Assessment!$R$5:$R$33)/SUMPRODUCT((Assessment!$B$5:$B$33=A23)*Assessment!$G$5:$G$33*(Assessment!$N$5:$N$33<>"")),0)) | E23: =COUNTIFS(Assessment!$B$5:$B$33,A23,Assessment!$N$5:$N$33,"Satisfactory") -> 0 | F23: =COUNTIFS(Assessment!$B$5:$B$33,A23,Assessment!$N$5:$N$33,"Needs Attention") -> 0 | G23: =COUNTIFS(Assessment!$B$5:$B$33,A23,Assessment!$N$5:$N$33,"At Risk") -> 0 | H23: =IF(G23>0,"At Risk items present",IF(F23>0,"Needs Attention items present",IF(C23=0,"Not scored",""))) -> Not scored
A24: Strategic Alignment | B24: =COUNTIF(Assessment!$B$5:$B$33,A24) -> 4 | C24: =SUMPRODUCT((Assessment!$B$5:$B$33=A24)*(Assessment!$N$5:$N$33<>"")) -> 0 | D24: =IF(C24=0,"",ROUND(SUMPRODUCT((Assessment!$B$5:$B$33=A24)*Assessment!$G$5:$G$33*Assessment!$R$5:$R$33)/SUMPRODUCT((Assessment!$B$5:$B$33=A24)*Assessment!$G$5:$G$33*(Assessment!$N$5:$N$33<>"")),0)) | E24: =COUNTIFS(Assessment!$B$5:$B$33,A24,Assessment!$N$5:$N$33,"Satisfactory") -> 0 | F24: =COUNTIFS(Assessment!$B$5:$B$33,A24,Assessment!$N$5:$N$33,"Needs Attention") -> 0 | G24: =COUNTIFS(Assessment!$B$5:$B$33,A24,Assessment!$N$5:$N$33,"At Risk") -> 0 | H24: =IF(G24>0,"At Risk items present",IF(F24>0,"Needs Attention items present",IF(C24=0,"Not scored",""))) -> Not scored
A25: Risk Triggers | B25: =COUNTIF(Assessment!$B$5:$B$33,A25) -> 5 | C25: =SUMPRODUCT((Assessment!$B$5:$B$33=A25)*(Assessment!$N$5:$N$33<>"")) -> 0 | D25: =IF(C25=0,"",ROUND(SUMPRODUCT((Assessment!$B$5:$B$33=A25)*Assessment!$G$5:$G$33*Assessment!$R$5:$R$33)/SUMPRODUCT((Assessment!$B$5:$B$33=A25)*Assessment!$G$5:$G$33*(Assessment!$N$5:$N$33<>"")),0)) | E25: =COUNTIFS(Assessment!$B$5:$B$33,A25,Assessment!$N$5:$N$33,"Satisfactory") -> 0 | F25: =COUNTIFS(Assessment!$B$5:$B$33,A25,Assessment!$N$5:$N$33,"Needs Attention") -> 0 | G25: =COUNTIFS(Assessment!$B$5:$B$33,A25,Assessment!$N$5:$N$33,"At Risk") -> 0 | H25: =IF(G25>0,"At Risk items present",IF(F25>0,"Needs Attention items present",IF(C25=0,"Not scored",""))) -> Not scored
A27: Health x Profitability
A28: Agreement gross margin | B28: =IF('Client Info'!$B$19="","",'Client Info'!$B$19)
A29: Target margin | B29: =IF('Client Info'!$B$20="","",'Client Info'!$B$20)
A30: Profitability | B30: =IF(OR(B28="",B29=""),"Not entered",IF(B28>=B29,"Profitable","Below target")) -> Not entered
A31: Quadrant | B31: =IF(OR(F6="Not scored",B30="Not entered"),"Incomplete",IF(F6="Healthy",IF(B30="Profitable","Protect & Expand","Reprice"),IF(B30="Profitable","Rescue (Priority)","Fix or Exit"))) -> Incomplete
A32: Recommended play | B32: =IF(B31="Protect & Expand","Keep the cadence. Use the next QBR to propose the highest-value roadmap item and ask for a referral.",IF(B31="Reprice","The relationship can absorb a pricing conversation. Review scope, consumption, and rates before renewal, and present the adjustment tied to value delivered.",IF(B31="Rescue (Priority)","Highest blind-spot risk: the revenue is real and the relationship is eroding. Hold an executive-to-executive meeting within 30 days and assign an owner to every At Risk item.",IF(B31="Fix or Exit","Decide deliberately. Either build a 90-day recovery plan that includes repricing, or plan a professional, managed exit at renewal.","Complete the assessment and margin inputs to see the recommended play.")))) -> Complete the assessment and margin inputs to see the recommended play.
A34: Items requiring action (At Risk first)
A35: # | B35: ID | C35: Question | E35: Outcome | F35: Recommended play | H35: Evidence / notes
A36: =IF(B36="","",1) | B36: =IFERROR(INDEX(Assessment!$A$5:$A$33,MATCH(1,Assessment!$S$5:$S$33,0)),"") | C36: =IF(B36="","",INDEX(Assessment!$C$5:$C$33,MATCH(B36,Assessment!$A$5:$A$33,0))) | E36: =IF(B36="","",INDEX(Assessment!$N$5:$N$33,MATCH(B36,Assessment!$A$5:$A$33,0))) | F36: =IF(B36="","",INDEX(Assessment!$Q$5:$Q$33,MATCH(B36,Assessment!$A$5:$A$33,0))) | H36: =IF(B36="","",IF(INDEX(Assessment!$O$5:$O$33,MATCH(B36,Assessment!$A$5:$A$33,0))="","",INDEX(Assessment!$O$5:$O$33,MATCH(B36,Assessment!$A$5:$A$33,0))))
A37: =IF(B37="","",2) | B37: =IFERROR(INDEX(Assessment!$A$5:$A$33,MATCH(2,Assessment!$S$5:$S$33,0)),"") | C37: =IF(B37="","",INDEX(Assessment!$C$5:$C$33,MATCH(B37,Assessment!$A$5:$A$33,0))) | E37: =IF(B37="","",INDEX(Assessment!$N$5:$N$33,MATCH(B37,Assessment!$A$5:$A$33,0))) | F37: =IF(B37="","",INDEX(Assessment!$Q$5:$Q$33,MATCH(B37,Assessment!$A$5:$A$33,0))) | H37: =IF(B37="","",IF(INDEX(Assessment!$O$5:$O$33,MATCH(B37,Assessment!$A$5:$A$33,0))="","",INDEX(Assessment!$O$5:$O$33,MATCH(B37,Assessment!$A$5:$A$33,0))))
A38: =IF(B38="","",3) | B38: =IFERROR(INDEX(Assessment!$A$5:$A$33,MATCH(3,Assessment!$S$5:$S$33,0)),"") | C38: =IF(B38="","",INDEX(Assessment!$C$5:$C$33,MATCH(B38,Assessment!$A$5:$A$33,0))) | E38: =IF(B38="","",INDEX(Assessment!$N$5:$N$33,MATCH(B38,Assessment!$A$5:$A$33,0))) | F38: =IF(B38="","",INDEX(Assessment!$Q$5:$Q$33,MATCH(B38,Assessment!$A$5:$A$33,0))) | H38: =IF(B38="","",IF(INDEX(Assessment!$O$5:$O$33,MATCH(B38,Assessment!$A$5:$A$33,0))="","",INDEX(Assessment!$O$5:$O$33,MATCH(B38,Assessment!$A$5:$A$33,0))))
A39: =IF(B39="","",4) | B39: =IFERROR(INDEX(Assessment!$A$5:$A$33,MATCH(4,Assessment!$S$5:$S$33,0)),"") | C39: =IF(B39="","",INDEX(Assessment!$C$5:$C$33,MATCH(B39,Assessment!$A$5:$A$33,0))) | E39: =IF(B39="","",INDEX(Assessment!$N$5:$N$33,MATCH(B39,Assessment!$A$5:$A$33,0))) | F39: =IF(B39="","",INDEX(Assessment!$Q$5:$Q$33,MATCH(B39,Assessment!$A$5:$A$33,0))) | H39: =IF(B39="","",IF(INDEX(Assessment!$O$5:$O$33,MATCH(B39,Assessment!$A$5:$A$33,0))="","",INDEX(Assessment!$O$5:$O$33,MATCH(B39,Assessment!$A$5:$A$33,0))))
A40: =IF(B40="","",5) | B40: =IFERROR(INDEX(Assessment!$A$5:$A$33,MATCH(5,Assessment!$S$5:$S$33,0)),"") | C40: =IF(B40="","",INDEX(Assessment!$C$5:$C$33,MATCH(B40,Assessment!$A$5:$A$33,0))) | E40: =IF(B40="","",INDEX(Assessment!$N$5:$N$33,MATCH(B40,Assessment!$A$5:$A$33,0))) | F40: =IF(B40="","",INDEX(Assessment!$Q$5:$Q$33,MATCH(B40,Assessment!$A$5:$A$33,0))) | H40: =IF(B40="","",IF(INDEX(Assessment!$O$5:$O$33,MATCH(B40,Assessment!$A$5:$A$33,0))="","",INDEX(Assessment!$O$5:$O$33,MATCH(B40,Assessment!$A$5:$A$33,0))))
A41: =IF(B41="","",6) | B41: =IFERROR(INDEX(Assessment!$A$5:$A$33,MATCH(6,Assessment!$S$5:$S$33,0)),"") | C41: =IF(B41="","",INDEX(Assessment!$C$5:$C$33,MATCH(B41,Assessment!$A$5:$A$33,0))) | E41: =IF(B41="","",INDEX(Assessment!$N$5:$N$33,MATCH(B41,Assessment!$A$5:$A$33,0))) | F41: =IF(B41="","",INDEX(Assessment!$Q$5:$Q$33,MATCH(B41,Assessment!$A$5:$A$33,0))) | H41: =IF(B41="","",IF(INDEX(Assessment!$O$5:$O$33,MATCH(B41,Assessment!$A$5:$A$33,0))="","",INDEX(Assessment!$O$5:$O$33,MATCH(B41,Assessment!$A$5:$A$33,0))))
A42: =IF(B42="","",7) | B42: =IFERROR(INDEX(Assessment!$A$5:$A$33,MATCH(7,Assessment!$S$5:$S$33,0)),"") | C42: =IF(B42="","",INDEX(Assessment!$C$5:$C$33,MATCH(B42,Assessment!$A$5:$A$33,0))) | E42: =IF(B42="","",INDEX(Assessment!$N$5:$N$33,MATCH(B42,Assessment!$A$5:$A$33,0))) | F42: =IF(B42="","",INDEX(Assessment!$Q$5:$Q$33,MATCH(B42,Assessment!$A$5:$A$33,0))) | H42: =IF(B42="","",IF(INDEX(Assessment!$O$5:$O$33,MATCH(B42,Assessment!$A$5:$A$33,0))="","",INDEX(Assessment!$O$5:$O$33,MATCH(B42,Assessment!$A$5:$A$33,0))))
A43: =IF(B43="","",8) | B43: =IFERROR(INDEX(Assessment!$A$5:$A$33,MATCH(8,Assessment!$S$5:$S$33,0)),"") | C43: =IF(B43="","",INDEX(Assessment!$C$5:$C$33,MATCH(B43,Assessment!$A$5:$A$33,0))) | E43: =IF(B43="","",INDEX(Assessment!$N$5:$N$33,MATCH(B43,Assessment!$A$5:$A$33,0))) | F43: =IF(B43="","",INDEX(Assessment!$Q$5:$Q$33,MATCH(B43,Assessment!$A$5:$A$33,0))) | H43: =IF(B43="","",IF(INDEX(Assessment!$O$5:$O$33,MATCH(B43,Assessment!$A$5:$A$33,0))="","",INDEX(Assessment!$O$5:$O$33,MATCH(B43,Assessment!$A$5:$A$33,0))))
A44: =IF(B44="","",9) | B44: =IFERROR(INDEX(Assessment!$A$5:$A$33,MATCH(9,Assessment!$S$5:$S$33,0)),"") | C44: =IF(B44="","",INDEX(Assessment!$C$5:$C$33,MATCH(B44,Assessment!$A$5:$A$33,0))) | E44: =IF(B44="","",INDEX(Assessment!$N$5:$N$33,MATCH(B44,Assessment!$A$5:$A$33,0))) | F44: =IF(B44="","",INDEX(Assessment!$Q$5:$Q$33,MATCH(B44,Assessment!$A$5:$A$33,0))) | H44: =IF(B44="","",IF(INDEX(Assessment!$O$5:$O$33,MATCH(B44,Assessment!$A$5:$A$33,0))="","",INDEX(Assessment!$O$5:$O$33,MATCH(B44,Assessment!$A$5:$A$33,0))))
A45: =IF(B45="","",10) | B45: =IFERROR(INDEX(Assessment!$A$5:$A$33,MATCH(10,Assessment!$S$5:$S$33,0)),"") | C45: =IF(B45="","",INDEX(Assessment!$C$5:$C$33,MATCH(B45,Assessment!$A$5:$A$33,0))) | E45: =IF(B45="","",INDEX(Assessment!$N$5:$N$33,MATCH(B45,Assessment!$A$5:$A$33,0))) | F45: =IF(B45="","",INDEX(Assessment!$Q$5:$Q$33,MATCH(B45,Assessment!$A$5:$A$33,0))) | H45: =IF(B45="","",IF(INDEX(Assessment!$O$5:$O$33,MATCH(B45,Assessment!$A$5:$A$33,0))="","",INDEX(Assessment!$O$5:$O$33,MATCH(B45,Assessment!$A$5:$A$33,0))))
A46: =IF(B46="","",11) | B46: =IFERROR(INDEX(Assessment!$A$5:$A$33,MATCH(11,Assessment!$S$5:$S$33,0)),"") | C46: =IF(B46="","",INDEX(Assessment!$C$5:$C$33,MATCH(B46,Assessment!$A$5:$A$33,0))) | E46: =IF(B46="","",INDEX(Assessment!$N$5:$N$33,MATCH(B46,Assessment!$A$5:$A$33,0))) | F46: =IF(B46="","",INDEX(Assessment!$Q$5:$Q$33,MATCH(B46,Assessment!$A$5:$A$33,0))) | H46: =IF(B46="","",IF(INDEX(Assessment!$O$5:$O$33,MATCH(B46,Assessment!$A$5:$A$33,0))="","",INDEX(Assessment!$O$5:$O$33,MATCH(B46,Assessment!$A$5:$A$33,0))))
...

Sheet Thresholds
A1: Scoring Thresholds
A2: Defaults are starting points. Tune them to your service standards; criteria text on the Assessment tab updates automatically.
